Workbook

Sheet Soru Listesi
A1: İDEAL DURUM ID | B1: İNCELEME KONUSU ID | C1: KONU | D1: AĞIRLIK | E1: İDEAL DURUM | F1: İNCELEME KONUSU | G1: KONU ID
A2: A1.1 | B2: A | C2: DESTEK | D2: 2 | E2: YÖNETİM İSRAFLA MÜCADELE VE SÜREÇLERİN İYİLEŞTİRİLMESİ KONUSUNDA FARKINDALIK ÇALIŞMALARINI BAŞLATMIŞ, BUNUN İÇİN KAYNAK VE ZAMAN AYIRIYOR | F2: YÖNETİMİN KATILIMI VE DESTEĞİ | G2: A1
A3: A2.1 | B3: A | C3: FARKINDALIK OLUŞTURMA | D3: 1 | E3: İYİLEŞTİRME SÜREÇLERİNE DİKKAT ÇEKMEK İÇİN KAMPANYALAR, SLOGANLAR, BİLGİLENDİRME AFİŞLER GİBİ ARAÇLARLA ÇALIŞANLARDAN FARKINDALIK YARATIYOR. | F3: YÖNETİMİN KATILIMI VE DESTEĞİ | G3: A2
A4: A3.1 | B4: A | C4: ORGANİZASYON | D4: 1.5 | E4: SAHANIN VE İŞLETMENİN ORGANİZASYON YAPISI SÜREKLİ GELİŞİM FAALİYETLERİNİ DESTEKLENMESİNE HİZMET ETMEKTEDİR. SÜREKLİ GELİŞİM İÇİN ROLLER VE GÖREVLER BELİRLENMİŞ EN AZ BİR KİŞİ / DEPARTMAN TARAFINDAN TAKİBİ YAPTIRILMAKTADIR. | F4: YÖNETİMİN KATILIMI VE DESTEĞİ | G4: A3
A5: A4.1 | B5: A | C5: RAPORLAMA | D5: 2 | E5: YAPILAN İYİLEŞTİRİCİ FAALİYETLER PERİODİK OLARAK SORUMLULAR TARAFINDAN YÖNETİME RAPORLANIR. YAPILAN ÇALIŞMALAR ÜST YÖNETİM EKİBİ TARAFINDAN TAKİP EDİLEREK SÜREÇLERİN GELİŞİMİ İZLENİR. | F5: YÖNETİMİN KATILIMI VE DESTEĞİ | G5: A4
A6: A5.1 | B6: A | C6: VİZYON | D6: 1.5 | E6: İŞLETME VİZYONU BELİRLİ, GÖRSEL OLARAK İZLENEBİLİYOR VE HERKES TARAFINDAN BİLİNİYOR DESTEKLİYOR. VİZYONU GERÇEKLEŞTİRMEDE KATILIMCI YÖNETİMİN ALT YAPISI MEVCUTTUR. | F6: YÖNETİMİN KATILIMI VE DESTEĞİ | G6: A5
A7: A6.1 | B7: A | C7: HEDEFLER - STRATEJİLER | D7: 1.5 | E7: ÜST YÖNETİM UZUN VADELİ HEDEFLERE ULAŞMAK İÇİN ORTA VADELİ HEDEF VE STRATEJİLERİ BELİRLEMİŞ, BU STRATEJİLERİ DEPARTMAN YÖNETİCİLERİ İLE PAYLAŞARAK YILLIK PROGRAMLARA DÖKMÜŞTÜR. | F7: YÖNETİMİN KATILIMI VE DESTEĞİ | G7: A6
A8: A7.1 | B8: A | C8: 5 ANA MİSYON | D8: 3 | E8: ŞİRKETİN ANA HEDEFLERİ 5 ANA MİSYONA HİZMET ETMEKTEDİR. ANA HEDEFLER KALİTE, MALİYET, SEVKİYAT, (ÜRETİM,BAKIM), İŞ GÜVENLİĞİ, İNSAN KAYNAKLARI VB. GİBİ ŞİRKETİN GELİŞİMESİ İÇİN ÖNEMLİ NOKTALARI İÇERMEKTEDİR. | F8: YÖNETİMİN KATILIMI VE DESTEĞİ | G8: A7
A9: A8.1 | B9: A | C9: KATILIMCI YÖNETİM | D9: 3 | E9: ANA HEDEFLERİ DESTEKLEYEN ALT HEDEFLER, DEPARTMAN YÖNETİCİLERİ TARAFINDAN BELİRLENMİŞ, DEPARTMAN İÇİNDEKİ TÜM SEVİYERELERE HEDEFLERİN YAYILIMI SAĞLANMIŞTIR. | F9: YÖNETİMİN KATILIMI VE DESTEĞİ | G9: A8
A10: A9.1 | B10: A | C10: HEDEF TAKİP | D10: 2 | E10: DEPARTMANLARIN FAALİYETLERİ İZLENEBİLİR BİR YAPIDADIR. AYLIK FAALİYETLER -HEDEF GERÇEKLEŞME SONUÇLARI - HOSHIN / B.S.C ( BALANCE SCORECARD) GİBİ YAPILARLA AYLIK OLARAK YÖNDETİMİNDE KATILDIĞI TOPLANTILARLA TAKİP EDİLİR (VE SONUÇLAR GÖRSELLEŞTİRİLİR. ) | F10: YÖNETİMİN KATILIMI VE DESTEĞİ | G10: A9
A11: A10.1 | B11: A | C11: ANALİZ | D11: 2.5 | E11: GERÇEKLEŞMEYEN HEDEFLERE KARŞI ANALİZLER YAPILIR, UYGUNSUZLUKLARIN KÖK NEDENLERİ TESPİT EDİLEREK YENİ YÖNTEM VE KNOW HOW ELDE EDİLMESİ SAĞLANIR. | F11: YÖNETİMİN KATILIMI VE DESTEĞİ | G11: A10
A12: B1.1 | B12: B | C12: KAR ODAKLILIK | D12: 3 | E12: YILLIK HEDEF PLANLARI BİR BÜTÇE DAHİLİNDE OLUŞTURULMUŞ, HEDEFLENEN KAR ORANI BELİRLENMİŞTİR. İSTENİLEN KARLILIĞA ULAŞABİLMEK İÇİN ODAKLANILMIŞ MAALİYET AZALTICI PROGRAMLAR OLUŞTURULARAK TAKİP EDİLMEKTEDİR | F12: DEĞER & MALİYET YÖNETİMİ | G12: B1
A13: B2.1 | B13: B | C13: OPERASYONEL MALİTET | D13: 3 | E13: DİREK OPERASYON VE ÜRETİM FAALİYETLERİNDE MALİYET İLE İLİŞKİLİ HEDEFLER TAKİP EDİLMEKTEDİR. MALİYET UNUSURLARI OLUŞTURULAN FAKTÖRLERE SORUMLULAR ATANARAK MAALİYET AZALTICI ALT FAALİYETLER SÜREKLİ YÜRTÜLMEKTEDİR. | F13: DEĞER & MALİYET YÖNETİMİ | G13: B2
... A165: S6.1 | B165: S | C165: RAPORLAMA | D165: 3 | E165: OLUŞAN HENKATEN MADDELERİ RAPORLANIR, KAYIT ALTINA ALINARAK AKSİYONLARI İLE BİRLİKTE KURUM HAFIZASINDA SAKLANIR. ÜRETİMİN AKSİYON KABİLİYETİ GELİŞTİRİLİR. | F165: HENKATEN YÖNETİMİ | G165: S6

Sheet Veriler
A1: IDID | B1: PUAN | C1: SONUÇ | D1: NOTLAR | F1: Firma Adı | G1: Rapor Tarihi | H1: Rapor No | I1: Denetleme Tarihi | J1: Hedef Puan | K1: Firma Katılımcıları | L1: Denetleyiciler | M1: DeğerlendirmeSonuc1 | N1: DeğerlendirmeSonuc2 | O1: DeğerlendirmeSonuc3 | Q1: KONU ID | R1: SONUÇ | T1: DENETLEME NO | U1: DENETLEME SONUÇ | V1: DENETLEME SEVİYE | X1: KONU ID | Y1: KONU YORUM | AA1: BEST KONU ID

Sheet 1
H17: SÜREÇ DEĞERLENDİRME RAPORU
H20: =DenetlemeBilgileri[Firma Adı]
H24: RAPOR TARİHİ: | J24: =Veriler!G2
H25: RAPOR NO: | J25: =Veriler!H2

Sheet 2
I3: KONSEPT
D10: 1 - DEĞERLENDİRME METODU
D12: 2 - SONUÇ ÖZET TABLO
D14: 3 - FIRSATLAR
D16: 4 - DEĞERLENDİRME İÇERİĞİ
D18: 5 - SONUÇ
B27: GEMPA PARTNER MÜHENDİSLİK VE YAZILIM A.Ş.

Sheet 3
C2: DEĞERLENDİRME METODU

Sheet 4
I3: DEĞERLENDİRME METODU
D6: HEDEF PUAN BELİRLEME
D10: KRİTER | H10: SEVİYE | J10: PUAN
D11: SÜREKLİ GELİŞİM ÇALIŞMALARI BAŞLAMIŞ, KAİZEN KÜLTÜRÜ SAHAYA YANSITILMIŞ, VİZYON NET VE İZLENEBİLİR DÜZEYDEDİR. | H11: A | J11: 70
D16: SÜREKLİ GELİŞİM HENÜZ BAŞLAMAMIŞ, HEDEFLER VE SONUÇLAR İZLENEBİLİR DEĞİLDİR. | H16: B | J16: 45
D22: ="HEDEF PUAN: " & Veriler!J2
B27: GEMPA PARTNER MÜHENDİSLİK VE YAZILIM A.Ş.

Sheet 5
I3: DEĞERLENDİRME METODU
D6: DEĞERLENDİRME KRİTERLERİ
D9: DEĞERLENDİRME KONULARI | I9: PUANLAMA TANIMI
A10: A | D10: 1 | E10: =VLOOKUP(A10,'Soru Listesi'!B:F,5,0) | I10: 0 | J10: ÇALIŞMA YOK
A11: B | D11: 2 | E11: =VLOOKUP(A11,'Soru Listesi'!B:F,5,0)
A12: C | D12: 3 | E12: =VLOOKUP(A12,'Soru Listesi'!B:F,5,0) | I12: 1 | J12: ÇALIŞMA HENÜZ BAŞLAMAMIŞ
A13: D | D13: 4 | E13: =VLOOKUP(A13,'Soru Listesi'!B:F,5,0)
A14: E | D14: 5 | E14: =VLOOKUP(A14,'Soru Listesi'!B:F,5,0) | I14: 2 | J14: ÇALIŞMA VAR AMA ETKİN KULLANILMIYOR
A15: F | D15: 6 | E15: =VLOOKUP(A15,'Soru Listesi'!B:F,5,0)
A16: G | D16: 7 | E16: =VLOOKUP(A16,'Soru Listesi'!B:F,5,0) | I16: 3 | J16: ÇALIŞMA VAR AMA STANDARTLAŞTIRILMAMIŞ
A17: H | D17: 8 | E17: =VLOOKUP(A17,'Soru Listesi'!B:F,5,0)
A18: I | D18: 9 | E18: =VLOOKUP(A18,'Soru Listesi'!B:F,5,0) | I18: 4 | J18: BAŞARILI - İYİLEŞTİRİLMEYE AÇIK
A19: J | D19: 10 | E19: =VLOOKUP(A19,'Soru Listesi'!B:F,5,0)
A20: K | D20: 11 | E20: =VLOOKUP(A20,'Soru Listesi'!B:F,5,0) | I20: 5 | J20: BAŞARILI - BEST PRACTICE
A21: L | D21: 12 | E21: =VLOOKUP(A21,'Soru Listesi'!B:F,5,0)
A22: M | D22: 13 | E22: =VLOOKUP(A22,'Soru Listesi'!B:F,5,0)
A23: N | D23: 14 | E23: =VLOOKUP(A23,'Soru Listesi'!B:F,5,0)
A24: O | D24: 15 | E24: =VLOOKUP(A24,'Soru Listesi'!B:F,5,0)
A25: P | D25: 16 | E25: =VLOOKUP(A25,'Soru Listesi'!B:F,5,0)
A26: R | D26: 17 | E26: =VLOOKUP(A26,'Soru Listesi'!B:F,5,0)
A27: S | D27: 18 | E27: =VLOOKUP(A27,'Soru Listesi'!B:F,5,0)
B28: GEMPA PARTNER MÜHENDİSLİK VE YAZILIM A.Ş.

Sheet 6
I3: DEĞERLENDİRME METODU
C6: DEĞERLENDİRME SEVİYELERİ
H9: ▪ İsraf yoğun süreç akışı, isrflar tespit edilemez. Sürekli iyileştirme bilinci yeterli seviyede değildir.
H13: ▪ İsrafla mücadele için gerekli altyapı oluşturulmuş, farkındalık başlamıştır.
H17: ▪ Dönüşüm başlamış, kültür değişikliği görünür düzeydedir. Gelişim sağlanmaktaır.
H21: ▪Gelişim organiizasyonun her kademesinde sürdürülebilir düzeydedir.
H25: ▪ Olgunluk sağlanmış, sürekli gelişim görsel olarak fark edilmektedir. İsraflar kaynağında bertaraf edilmektedir.
B28: GEMPA PARTNER MÜHENDİSLİK VE YAZILIM A.Ş.

Sheet 7
C2: DEĞERLENDİRME ÖZET TABLO

Sheet 8
C3: SAHA İNCELEME RAPORU
C4: FİRMA İSMİ: | E4: =Veriler!F2
C5: DENETİM TARİHİ: | E5: =Veriler!I2 | H5: RAPOR TARİHİ: | J5: =Veriler!G2 | L5: RAPOR NO: | N5: =Veriler!H2
C6: FİRMA KATILIMCILARI: | E6: =Veriler!K2
C7: GEMBA PARTNER: | E7: =Veriler!L2
C8: SKOR: | E8: =IFERROR(LARGE(Veriler!T:T,1) & " .DENETLEME","") | H8: =IFERROR(LARGE(Veriler!T:T,2) & " .DENETLEME","") | H9: =IFERROR(VLOOKUP(LARGE(Veriler!T:T,2),Veriler!T:U,2,0),"") | E10: =IFERROR(VLOOKUP(LARGE(Veriler!T:T,1),Veriler!T:V,3,0),"")
C11: SONUÇ
C12: DEĞERLENDİRME KONULARI | G12: HEDEF | H12: SONUÇ
A13: A | C13: 1 | D13: =VLOOKUP(A13,'Soru Listesi'!B:F,5,0) | G13: =DenetlemeBilgileri[Hedef Puan] | H13: =VLOOKUP(A13,KategoriSonuc[#All],2,0)
A14: B | C14: 2 | D14: =VLOOKUP(A14,'Soru Listesi'!B:F,5,0) | G14: =DenetlemeBilgileri[Hedef Puan] | H14: =VLOOKUP(A14,KategoriSonuc[#All],2,0)
A15: C | C15: 3 | D15: =VLOOKUP(A15,'Soru Listesi'!B:F,5,0) | G15: =DenetlemeBilgileri[Hedef Puan] | H15: =VLOOKUP(A15,KategoriSonuc[#All],2,0)
A16: D | C16: 4 | D16: =VLOOKUP(A16,'Soru Listesi'!B:F,5,0) | G16: =DenetlemeBilgileri[Hedef Puan] | H16: =VLOOKUP(A16,KategoriSonuc[#All],2,0)
A17: E | C17: 5 | D17: =VLOOKUP(A17,'Soru Listesi'!B:F,5,0) | G17: =DenetlemeBilgileri[Hedef Puan] | H17: =VLOOKUP(A17,KategoriSonuc[#All],2,0)
A18: F | C18: 6 | D18: =VLOOKUP(A18,'Soru Listesi'!B:F,5,0) | G18: =DenetlemeBilgileri[Hedef Puan] | H18: =VLOOKUP(A18,KategoriSonuc[#All],2,0)
A19: G | C19: 7 | D19: =VLOOKUP(A19,'Soru Listesi'!B:F,5,0) | G19: =DenetlemeBilgileri[Hedef Puan] | H19: =VLOOKUP(A19,KategoriSonuc[#All],2,0)
A20: H | C20: 8 | D20: =VLOOKUP(A20,'Soru Listesi'!B:F,5,0) | G20: =DenetlemeBilgileri[Hedef Puan] | H20: =VLOOKUP(A20,KategoriSonuc[#All],2,0)
A21: I | C21: 9 | D21: =VLOOKUP(A21,'Soru Listesi'!B:F,5,0) | G21: =DenetlemeBilgileri[Hedef Puan] | H21: =VLOOKUP(A21,KategoriSonuc[#All],2,0)
A22: J | C22: 10 | D22: =VLOOKUP(A22,'Soru Listesi'!B:F,5,0) | G22: =DenetlemeBilgileri[Hedef Puan] | H22: =VLOOKUP(A22,KategoriSonuc[#All],2,0)
A23: K | C23: 11 | D23: =VLOOKUP(A23,'Soru Listesi'!B:F,5,0) | G23: =DenetlemeBilgileri[Hedef Puan] | H23: =VLOOKUP(A23,KategoriSonuc[#All],2,0)
A24: L | C24: 12 | D24: =VLOOKUP(A24,'Soru Listesi'!B:F,5,0) | G24: =DenetlemeBilgileri[Hedef Puan] | H24: =VLOOKUP(A24,KategoriSonuc[#All],2,0)
... A30: S | C30: 18 | D30: =VLOOKUP(A30,'Soru Listesi'!B:F,5,0) | G30: =DenetlemeBilgileri[Hedef Puan] | H30: =VLOOKUP(A30,KategoriSonuc[#All],2,0)
B31: GEMPA PARTNER MÜHENDİSLİK VE YAZILIM A.Ş.

Sheet 9
O2: =VLOOKUP(MAX(Veriler!T:T,1),Veriler!T:U,2,0)
I3: DEĞERLENDİRME ÖZETİ
C6: DEĞERLENDİRME SEVİYELERİ
H9: ▪ İsraf yoğun süreç akışı, isrflar tespit edilemez. Sürekli iyileştirme bilinci yeterli seviyede değildir.
H13: ▪ İsrafla mücadele için gerekli altyapı oluşturulmuş, farkındalık başlamıştır.
H17: ▪ Dönüşüm başlamış, kültür değişikliği görünür düzeydedir. Gelişim sağlanmaktaır.
H21: ▪Gelişim organiizasyonun her kademesinde sürdürülebilir düzeydedir.
H25: ▪ Olgunluk sağlanmış, sürekli gelişim görsel olarak fark edilmektedir. İsraflar kaynağında bertaraf edilmektedir.
B28: GEMPA PARTNER MÜHENDİSLİK VE YAZILIM A.Ş.

Sheet 10
C2: DEĞERLENDİRME ÖZETİ

Sheet 11
I3: DEĞERLENDİRME ÖZETİ
A6: A | B6: =A6& "- " &VLOOKUP(A6,'Soru Listesi'!B:F,5,0) | D6: =VLOOKUP(A6,Veriler!X:Y,2,0)
A9: B | B9: =A9& "- " &VLOOKUP(A9,'Soru Listesi'!B:F,5,0) | D9: =VLOOKUP(A9,Veriler!X:Y,2,0)
A12: C | B12: =A12& "- " &VLOOKUP(A12,'Soru Listesi'!B:F,5,0) | D12: =VLOOKUP(A12,Veriler!X:Y,2,0)
A15: D | B15: =A15& "- " &VLOOKUP(A15,'Soru Listesi'!B:F,5,0) | D15: =VLOOKUP(A15,Veriler!X:Y,2,0)
A18: E | B18: =A18& "- " &VLOOKUP(A18,'Soru Listesi'!B:F,5,0) | D18: =VLOOKUP(A18,Veriler!X:Y,2,0)
A21: F | B21: =A21& "- " &VLOOKUP(A21,'Soru Listesi'!B:F,5,0) | D21: =VLOOKUP(A21,Veriler!X:Y,2,0)
A24: G | B24: =A24& "- " &VLOOKUP(A24,'Soru Listesi'!B:F,5,0) | D24: =VLOOKUP(A24,Veriler!X:Y,2,0)
B27: GEMPA PARTNER MÜHENDİSLİK VE YAZILIM A.Ş.

Sheet 12
I3: DEĞERLENDİRME ÖZETİ
A6: H | B6: =A6& "- " &VLOOKUP(A6,'Soru Listesi'!B:F,5,0) | D6: =VLOOKUP(A6,Veriler!X:Y,2,0)
A9: I | B9: =A9& "- " &VLOOKUP(A9,'Soru Listesi'!B:F,5,0) | D9: =VLOOKUP(A9,Veriler!X:Y,2,0)
A12: J | B12: =A12& "- " &VLOOKUP(A12,'Soru Listesi'!B:F,5,0) | D12: =VLOOKUP(A12,Veriler!X:Y,2,0)
A15: K | B15: =A15& "- " &VLOOKUP(A15,'Soru Listesi'!B:F,5,0) | D15: =VLOOKUP(A15,Veriler!X:Y,2,0)
A18: L | B18: =A18& "- " &VLOOKUP(A18,'Soru Listesi'!B:F,5,0) | D18: =VLOOKUP(A18,Veriler!X:Y,2,0)
A21: M | B21: =A21& "- " &VLOOKUP(A21,'Soru Listesi'!B:F,5,0) | D21: =VLOOKUP(A21,Veriler!X:Y,2,0)
A24: N | B24: =A24& "- " &VLOOKUP(A24,'Soru Listesi'!B:F,5,0) | D24: =VLOOKUP(A24,Veriler!X:Y,2,0)
B27: GEMPA PARTNER MÜHENDİSLİK VE YAZILIM A.Ş.

Sheet 13
I3: DEĞERLENDİRME ÖZETİ
A6: O | B6: =A6& "- " &VLOOKUP(A6,'Soru Listesi'!B:F,5,0) | D6: =VLOOKUP(A6,Veriler!X:Y,2,0)
A9: P | B9: =A9& "- " &VLOOKUP(A9,'Soru Listesi'!B:F,5,0) | D9: =VLOOKUP(A9,Veriler!X:Y,2,0)
A12: R | B12: =A12& "- " &VLOOKUP(A12,'Soru Listesi'!B:F,5,0) | D12: =VLOOKUP(A12,Veriler!X:Y,2,0)
A15: S | B15: =A15& "- " &VLOOKUP(A15,'Soru Listesi'!B:F,5,0) | D15: =VLOOKUP(A15,Veriler!X:Y,2,0)
B27: GEMPA PARTNER MÜHENDİSLİK VE YAZILIM A.Ş.

Sheet 14
I3: BEST PRACTICE UYGULAMALAR
C6: =IFERROR(VLOOKUP(Veriler!AA2,'Soru Listesi'!A:F,6,0) & " - " & VLOOKUP(Veriler!AA2,'Soru Listesi'!A:F,3,0),"")

Sheet A-0
C2: =(CODE(UPPER(MID(CELL("dosyaadı",A1),FIND("]",CELL("dosyaadı",A1),1)+1,1)))-CODE("A")+1) & " - " &VLOOKUP(MID(CELL("dosyaadı",A1),FIND("]",CELL("dosyaadı",A1),1)+1,1),'Soru Listesi'!B:F,5,0)

Sheet A-1
B1: # | C1: =VLOOKUP(A3,'Soru Listesi'!A:F,6,0)
A2: SORU ID | C2: TESPİT | D2: İDEAL DURUM | E2: PUAN DAĞILIMI
A3: A1.1 | B3: =VLOOKUP(A3,'Soru Listesi'!A:G,3,0) | C3: =VLOOKUP(A3,Veriler!A:D,4,0) | D3: =VLOOKUP(A3,'Soru Listesi'!A:G,5,0)
A4: A2.1 | B4: =VLOOKUP(A4,'Soru Listesi'!A:G,3,0) | C4: =VLOOKUP(A4,Veriler!A:D,4,0) | D4: =VLOOKUP(A4,'Soru Listesi'!A:G,5,0)
A5: A3.1 | B5: =VLOOKUP(A5,'Soru Listesi'!A:G,3,0) | C5: =VLOOKUP(A5,Veriler!A:D,4,0) | D5: =VLOOKUP(A5,'Soru Listesi'!A:G,5,0)
A6: A4.1 | B6: =VLOOKUP(A6,'Soru Listesi'!A:G,3,0) | C6: =VLOOKUP(A6,Veriler!A:D,4,0) | D6: =VLOOKUP(A6,'Soru Listesi'!A:G,5,0)
A7: A5.1 | B7: =VLOOKUP(A7,'Soru Listesi'!A:G,3,0) | C7: =VLOOKUP(A7,Veriler!A:D,4,0) | D7: =VLOOKUP(A7,'Soru Listesi'!A:G,5,0)
B10: ID | C10: KONU | D10: PUAN
B11: A1.1 | C11: =VLOOKUP(B11,'Soru Listesi'!A:C,3,0) | D11: =VLOOKUP(B11,Veriler!A:B,2,0)
B12: A2.1 | C12: =VLOOKUP(B12,'Soru Listesi'!A:C,3,0) | D12: =VLOOKUP(B12,Veriler!A:B,2,0)
B13: A3.1 | C13: =VLOOKUP(B13,'Soru Listesi'!A:C,3,0) | D13: =VLOOKUP(B13,Veriler!A:B,2,0)
B14: A4.1 | C14: =VLOOKUP(B14,'Soru Listesi'!A:C,3,0) | D14: =VLOOKUP(B14,Veriler!A:B,2,0)
B15: A5.1 | C15: =VLOOKUP(B15,'Soru Listesi'!A:C,3,0) | D15: =VLOOKUP(B15,Veriler!A:B,2,0)
B16: A6.1 | C16: =VLOOKUP(B16,'Soru Listesi'!A:C,3,0) | D16: =VLOOKUP(B16,Veriler!A:B,2,0)
B17: A7.1 | C17: =VLOOKUP(B17,'Soru Listesi'!A:C,3,0) | D17: =VLOOKUP(B17,Veriler!A:B,2,0)
B18: A8.1 | C18: =VLOOKUP(B18,'Soru Listesi'!A:C,3,0) | D18: =VLOOKUP(B18,Veriler!A:B,2,0)
B19: A9.1 | C19: =VLOOKUP(B19,'Soru Listesi'!A:C,3,0) | D19: =VLOOKUP(B19,Veriler!A:B,2,0)
B20: A10.1 | C20: =VLOOKUP(B20,'Soru Listesi'!A:C,3,0) | D20: =VLOOKUP(B20,Veriler!A:B,2,0)

Sheet A-2
B1: # | C1: =VLOOKUP(A3,'Soru Listesi'!A:F,6,0)
A2: SORU ID | C2: TESPİT | D2: İDEAL DURUM | E2: PUAN DAĞILIMI
A3: A6.1 | B3: =VLOOKUP(A3,'Soru Listesi'!A:G,3,0) | C3: =VLOOKUP(A3,Veriler!A:D,4,0) | D3: =VLOOKUP(A3,'Soru Listesi'!A:G,5,0)
A4: A7.1 | B4: =VLOOKUP(A4,'Soru Listesi'!A:G,3,0) | C4: =VLOOKUP(A4,Veriler!A:D,4,0) | D4: =VLOOKUP(A4,'Soru Listesi'!A:G,5,0)
A5: A8.1 | B5: =VLOOKUP(A5,'Soru Listesi'!A:G,3,0) | C5: =VLOOKUP(A5,Veriler!A:D,4,0) | D5: =VLOOKUP(A5,'Soru Listesi'!A:G,5,0)
A6: A9.1 | B6: =VLOOKUP(A6,'Soru Listesi'!A:G,3,0) | C6: =VLOOKUP(A6,Veriler!A:D,4,0) | D6: =VLOOKUP(A6,'Soru Listesi'!A:G,5,0)
A7: A10.1 | B7: =VLOOKUP(A7,'Soru Listesi'!A:G,3,0) | C7: =VLOOKUP(A7,Veriler!A:D,4,0) | D7: =VLOOKUP(A7,'Soru Listesi'!A:G,5,0)
B10: ID | C10: KONU | D10: PUAN
B11: A1.1 | C11: =VLOOKUP(B11,'Soru Listesi'!A:C,3,0) | D11: =VLOOKUP(B11,Veriler!A:B,2,0)
B12: A2.1 | C12: =VLOOKUP(B12,'Soru Listesi'!A:C,3,0) | D12: =VLOOKUP(B12,Veriler!A:B,2,0)
B13: A3.1 | C13: =VLOOKUP(B13,'Soru Listesi'!A:C,3,0) | D13: =VLOOKUP(B13,Veriler!A:B,2,0)
B14: A4.1 | C14: =VLOOKUP(B14,'Soru Listesi'!A:C,3,0) | D14: =VLOOKUP(B14,Veriler!A:B,2,0)
B15: A5.1 | C15: =VLOOKUP(B15,'Soru Listesi'!A:C,3,0) | D15: =VLOOKUP(B15,Veriler!A:B,2,0)
B16: A6.1 | C16: =VLOOKUP(B16,'Soru Listesi'!A:C,3,0) | D16: =VLOOKUP(B16,Veriler!A:B,2,0)
B17: A7.1 | C17: =VLOOKUP(B17,'Soru Listesi'!A:C,3,0) | D17: =VLOOKUP(B17,Veriler!A:B,2,0)
B18: A8.1 | C18: =VLOOKUP(B18,'Soru Listesi'!A:C,3,0) | D18: =VLOOKUP(B18,Veriler!A:B,2,0)
B19: A9.1 | C19: =VLOOKUP(B19,'Soru Listesi'!A:C,3,0) | D19: =VLOOKUP(B19,Veriler!A:B,2,0)
B20: A10.1 | C20: =VLOOKUP(B20,'Soru Listesi'!A:C,3,0) | D20: =VLOOKUP(B20,Veriler!A:B,2,0)

Sheet B-0
C2: =(CODE(UPPER(MID(CELL("dosyaadı",A1),FIND("]",CELL("dosyaadı",A1),1)+1,1)))-CODE("A")+1) & " - " &VLOOKUP(MID(CELL("dosyaadı",A1),FIND("]",CELL("dosyaadı",A1),1)+1,1),'Soru Listesi'!B:F,5,0)

Sheet B-1
B1: # | C1: =VLOOKUP(A3,'Soru Listesi'!A:F,6,0)
A2: SORU ID | C2: TESPİT | D2: İDEAL DURUM | E2: PUAN DAĞILIMI
A3: B1.1 | B3: =VLOOKUP(A3,'Soru Listesi'!A:G,3,0) | C3: =VLOOKUP(A3,Veriler!A:D,4,0) | D3: =VLOOKUP(A3,'Soru Listesi'!A:G,5,0)
A4: B2.1 | B4: =VLOOKUP(A4,'Soru Listesi'!A:G,3,0) | C4: =VLOOKUP(A4,Veriler!A:D,4,0) | D4: =VLOOKUP(A4,'Soru Listesi'!A:G,5,0)
A5: B3.1 | B5: =VLOOKUP(A5,'Soru Listesi'!A:G,3,0) | C5: =VLOOKUP(A5,Veriler!A:D,4,0) | D5: =VLOOKUP(A5,'Soru Listesi'!A:G,5,0)
A6: B4.1 | B6: =VLOOKUP(A6,'Soru Listesi'!A:G,3,0) | C6: =VLOOKUP(A6,Veriler!A:D,4,0) | D6: =VLOOKUP(A6,'Soru Listesi'!A:G,5,0)
A7: B5.1 | B7: =VLOOKUP(A7,'Soru Listesi'!A:G,3,0) | C7: =VLOOKUP(A7,Veriler!A:D,4,0) | D7: =VLOOKUP(A7,'Soru Listesi'!A:G,5,0)
B10: ID | C10: KONU | D10: PUAN
B11: B1.1 | C11: =VLOOKUP(B11,'Soru Listesi'!A:C,3,0) | D11: =VLOOKUP(B11,Veriler!A:B,2,0)
B12: B2.1 | C12: =VLOOKUP(B12,'Soru Listesi'!A:C,3,0) | D12: =VLOOKUP(B12,Veriler!A:B,2,0)
B13: B3.1 | C13: =VLOOKUP(B13,'Soru Listesi'!A:C,3,0) | D13: =VLOOKUP(B13,Veriler!A:B,2,0)
B14: B4.1 | C14: =VLOOKUP(B14,'Soru Listesi'!A:C,3,0) | D14: =VLOOKUP(B14,Veriler!A:B,2,0)
B15: B5.1 | C15: =VLOOKUP(B15,'Soru Listesi'!A:C,3,0) | D15: =VLOOKUP(B15,Veriler!A:B,2,0)
B16: B6.1 | C16: =VLOOKUP(B16,'Soru Listesi'!A:C,3,0) | D16: =VLOOKUP(B16,Veriler!A:B,2,0)
B17: B7.1 | C17: =VLOOKUP(B17,'Soru Listesi'!A:C,3,0) | D17: =VLOOKUP(B17,Veriler!A:B,2,0)
B18: B8.1 | C18: =VLOOKUP(B18,'Soru Listesi'!A:C,3,0) | D18: =VLOOKUP(B18,Veriler!A:B,2,0)

Sheet B-2
B1: # | C1: =VLOOKUP(A3,'Soru Listesi'!A:F,6,0)
A2: SORU ID | C2: TESPİT | D2: İDEAL DURUM | E2: PUAN DAĞILIMI
A3: B6.1 | B3: =VLOOKUP(A3,'Soru Listesi'!A:G,3,0) | C3: =VLOOKUP(A3,Veriler!A:D,4,0) | D3: =VLOOKUP(A3,'Soru Listesi'!A:G,5,0)
A4: B7.1 | B4: =VLOOKUP(A4,'Soru Listesi'!A:G,3,0) | C4: =VLOOKUP(A4,Veriler!A:D,4,0) | D4: =VLOOKUP(A4,'Soru Listesi'!A:G,5,0)
A5: B8.1 | B5: =VLOOKUP(A5,'Soru Listesi'!A:G,3,0) | C5: =VLOOKUP(A5,Veriler!A:D,4,0) | D5: =VLOOKUP(A5,'Soru Listesi'!A:G,5,0)
B10: ID | C10: KONU | D10: PUAN
B11: B1.1 | C11: =VLOOKUP(B11,'Soru Listesi'!A:C,3,0) | D11: =VLOOKUP(B11,Veriler!A:B,2,0)
B12: B2.1 | C12: =VLOOKUP(B12,'Soru Listesi'!A:C,3,0) | D12: =VLOOKUP(B12,Veriler!A:B,2,0)
B13: B3.1 | C13: =VLOOKUP(B13,'Soru Listesi'!A:C,3,0) | D13: =VLOOKUP(B13,Veriler!A:B,2,0)
B14: B4.1 | C14: =VLOOKUP(B14,'Soru Listesi'!A:C,3,0) | D14: =VLOOKUP(B14,Veriler!A:B,2,0)
B15: B5.1 | C15: =VLOOKUP(B15,'Soru Listesi'!A:C,3,0) | D15: =VLOOKUP(B15,Veriler!A:B,2,0)
B16: B6.1 | C16: =VLOOKUP(B16,'Soru Listesi'!A:C,3,0) | D16: =VLOOKUP(B16,Veriler!A:B,2,0)
B17: B7.1 | C17: =VLOOKUP(B17,'Soru Listesi'!A:C,3,0) | D17: =VLOOKUP(B17,Veriler!A:B,2,0)
B18: B8.1 | C18: =VLOOKUP(B18,'Soru Listesi'!A:C,3,0) | D18: =VLOOKUP(B18,Veriler!A:B,2,0)

Sheet C-0
C2: =(CODE(UPPER(MID(CELL("dosyaadı",A1),FIND("]",CELL("dosyaadı",A1),1)+1,1)))-CODE("A")+1) & " - " &VLOOKUP(MID(CELL("dosyaadı",A1),FIND("]",CELL("dosyaadı",A1),1)+1,1),'Soru Listesi'!B:F,5,0)

Sheet C-1
B1: # | C1: =VLOOKUP(A3,'Soru Listesi'!A:F,6,0)
A2: SORU ID | C2: TESPİT | D2: İDEAL DURUM | E2: PUAN DAĞILIMI
A3: C1.1 | B3: =VLOOKUP(A3,'Soru Listesi'!A:G,3,0) | C3: =VLOOKUP(A3,Veriler!A:D,4,0) | D3: =VLOOKUP(A3,'Soru Listesi'!A:G,5,0)
A4: C2.1 | B4: =VLOOKUP(A4,'Soru Listesi'!A:G,3,0) | C4: =VLOOKUP(A4,Veriler!A:D,4,0) | D4: =VLOOKUP(A4,'Soru Listesi'!A:G,5,0)
A5: C2.2 | B5: =VLOOKUP(A5,'Soru Listesi'!A:G,3,0) | C5: =VLOOKUP(A5,Veriler!A:D,4,0) | D5: =VLOOKUP(A5,'Soru Listesi'!A:G,5,0)
A6: C3.1 | B6: =VLOOKUP(A6,'Soru Listesi'!A:G,3,0) | C6: =VLOOKUP(A6,Veriler!A:D,4,0) | D6: =VLOOKUP(A6,'Soru Listesi'!A:G,5,0)
A7: C4.1 | B7: =VLOOKUP(A7,'Soru Listesi'!A:G,3,0) | C7: =VLOOKUP(A7,Veriler!A:D,4,0) | D7: =VLOOKUP(A7,'Soru Listesi'!A:G,5,0)
B10: ID | C10: KONU | D10: PUAN
B11: C1.1 | C11: =VLOOKUP(B11,'Soru Listesi'!A:C,3,0) | D11: =VLOOKUP(B11,Veriler!A:B,2,0)
B12: C2.1 | C12: =VLOOKUP(B12,'Soru Listesi'!A:C,3,0) | D12: =VLOOKUP(B12,Veriler!A:B,2,0)
B13: C2.2 | C13: =VLOOKUP(B13,'Soru Listesi'!A:C,3,0) | D13: =VLOOKUP(B13,Veriler!A:B,2,0)
B14: C3.1 | C14: =VLOOKUP(B14,'Soru Listesi'!A:C,3,0) | D14: =VLOOKUP(B14,Veriler!A:B,2,0)
B15: C4.1 | C15: =VLOOKUP(B15,'Soru Listesi'!A:C,3,0) | D15: =VLOOKUP(B15,Veriler!A:B,2,0)
B16: C5.1 | C16: =VLOOKUP(B16,'Soru Listesi'!A:C,3,0) | D16: =VLOOKUP(B16,Veriler!A:B,2,0)
B17: C6.1 | C17: =VLOOKUP(B17,'Soru Listesi'!A:C,3,0) | D17: =VLOOKUP(B17,Veriler!A:B,2,0)
B18: C7.1 | C18: =VLOOKUP(B18,'Soru Listesi'!A:C,3,0) | D18: =VLOOKUP(B18,Veriler!A:B,2,0)
B19: C8.1 | C19: =VLOOKUP(B19,'Soru Listesi'!A:C,3,0) | D19: =VLOOKUP(B19,Veriler!A:B,2,0)

Sheet C-2
B1: # | C1: =VLOOKUP(A3,'Soru Listesi'!A:F,6,0)
A2: SORU ID | C2: TESPİT | D2: İDEAL DURUM | E2: PUAN DAĞILIMI
A3: C5.1 | B3: =VLOOKUP(A3,'Soru Listesi'!A:G,3,0) | C3: =VLOOKUP(A3,Veriler!A:D,4,0) | D3: =VLOOKUP(A3,'Soru Listesi'!A:G,5,0)
A4: C6.1 | B4: =VLOOKUP(A4,'Soru Listesi'!A:G,3,0) | C4: =VLOOKUP(A4,Veriler!A:D,4,0) | D4: =VLOOKUP(A4,'Soru Listesi'!A:G,5,0)
A5: C7.1 | B5: =VLOOKUP(A5,'Soru Listesi'!A:G,3,0) | C5: =VLOOKUP(A5,Veriler!A:D,4,0) | D5: =VLOOKUP(A5,'Soru Listesi'!A:G,5,0)
A6: C8.1 | B6: =VLOOKUP(A6,'Soru Listesi'!A:G,3,0) | C6: =VLOOKUP(A6,Veriler!A:D,4,0) | D6: =VLOOKUP(A6,'Soru Listesi'!A:G,5,0)
B10: ID | C10: KONU | D10: PUAN
B11: C1.1 | C11: =VLOOKUP(B11,'Soru Listesi'!A:C,3,0) | D11: =VLOOKUP(B11,Veriler!A:B,2,0)
B12: C2.1 | C12: =VLOOKUP(B12,'Soru Listesi'!A:C,3,0) | D12: =VLOOKUP(B12,Veriler!A:B,2,0)
B13: C2.2 | C13: =VLOOKUP(B13,'Soru Listesi'!A:C,3,0) | D13: =VLOOKUP(B13,Veriler!A:B,2,0)
B14: C3.1 | C14: =VLOOKUP(B14,'Soru Listesi'!A:C,3,0) | D14: =VLOOKUP(B14,Veriler!A:B,2,0)
B15: C4.1 | C15: =VLOOKUP(B15,'Soru Listesi'!A:C,3,0) | D15: =VLOOKUP(B15,Veriler!A:B,2,0)
B16: C5.1 | C16: =VLOOKUP(B16,'Soru Listesi'!A:C,3,0) | D16: =VLOOKUP(B16,Veriler!A:B,2,0)
B17: C6.1 | C17: =VLOOKUP(B17,'Soru Listesi'!A:C,3,0) | D17: =VLOOKUP(B17,Veriler!A:B,2,0)
B18: C7.1 | C18: =VLOOKUP(B18,'Soru Listesi'!A:C,3,0) | D18: =VLOOKUP(B18,Veriler!A:B,2,0)
B19: C8.1 | C19: =VLOOKUP(B19,'Soru Listesi'!A:C,3,0) | D19: =VLOOKUP(B19,Veriler!A:B,2,0)

Sheet D-0
C2: =(CODE(UPPER(MID(CELL("dosyaadı",A1),FIND("]",CELL("dosyaadı",A1),1)+1,1)))-CODE("A")+1) & " - " &VLOOKUP(MID(CELL("dosyaadı",A1),FIND("]",CELL("dosyaadı",A1),1)+1,1),'Soru Listesi'!B:F,5,0)

Sheet D-1
B1: # | C1: =VLOOKUP(A3,'Soru Listesi'!A:F,6,0)
A2: SORU ID | C2: TESPİT | D2: İDEAL DURUM | E2: PUAN DAĞILIMI
A3: D1.1 | B3: =VLOOKUP(A3,'Soru Listesi'!A:G,3,0) | C3: =VLOOKUP(A3,Veriler!A:D,4,0) | D3: =VLOOKUP(A3,'Soru Listesi'!A:G,5,0)
A4: D2.1 | B4: =VLOOKUP(A4,'Soru Listesi'!A:G,3,0) | C4: =VLOOKUP(A4,Veriler!A:D,4,0) | D4: =VLOOKUP(A4,'Soru Listesi'!A:G,5,0)
A5: D3.1 | B5: =VLOOKUP(A5,'Soru Listesi'!A:G,3,0) | C5: =VLOOKUP(A5,Veriler!A:D,4,0) | D5: =VLOOKUP(A5,'Soru Listesi'!A:G,5,0)
A6: D4.1 | B6: =VLOOKUP(A6,'Soru Listesi'!A:G,3,0) | C6: =VLOOKUP(A6,Veriler!A:D,4,0) | D6: =VLOOKUP(A6,'Soru Listesi'!A:G,5,0)
A7: D5.1 | B7: =VLOOKUP(A7,'Soru Listesi'!A:G,3,0) | C7: =VLOOKUP(A7,Veriler!A:D,4,0) | D7: =VLOOKUP(A7,'Soru Listesi'!A:G,5,0)
B10: ID | C10: KONU | D10: PUAN
B11: D1.1 | C11: =VLOOKUP(B11,'Soru Listesi'!A:C,3,0) | D11: =VLOOKUP(B11,Veriler!A:B,2,0)
B12: D2.1 | C12: =VLOOKUP(B12,'Soru Listesi'!A:C,3,0) | D12: =VLOOKUP(B12,Veriler!A:B,2,0)
B13: D3.1 | C13: =VLOOKUP(B13,'Soru Listesi'!A:C,3,0) | D13: =VLOOKUP(B13,Veriler!A:B,2,0)
B14: D4.1 | C14: =VLOOKUP(B14,'Soru Listesi'!A:C,3,0) | D14: =VLOOKUP(B14,Veriler!A:B,2,0)
B15: D5.1 | C15: =VLOOKUP(B15,'Soru Listesi'!A:C,3,0) | D15: =VLOOKUP(B15,Veriler!A:B,2,0)
B16: D6.1 | C16: =VLOOKUP(B16,'Soru Listesi'!A:C,3,0) | D16: =VLOOKUP(B16,Veriler!A:B,2,0)
B17: D7.1 | C17: =VLOOKUP(B17,'Soru Listesi'!A:C,3,0) | D17: =VLOOKUP(B17,Veriler!A:B,2,0)
B18: D8.1 | C18: =VLOOKUP(B18,'Soru Listesi'!A:C,3,0) | D18: =VLOOKUP(B18,Veriler!A:B,2,0)
B19: D9.1 | C19: =VLOOKUP(B19,'Soru Listesi'!A:C,3,0) | D19: =VLOOKUP(B19,Veriler!A:B,2,0)
B20: D10.1 | C20: =VLOOKUP(B20,'Soru Listesi'!A:C,3,0) | D20: =VLOOKUP(B20,Veriler!A:B,2,0)
B21: D11.1 | C21: =VLOOKUP(B21,'Soru Listesi'!A:C,3,0) | D21: =VLOOKUP(B21,Veriler!A:B,2,0)
B22: D12.1 | C22: =VLOOKUP(B22,'Soru Listesi'!A:C,3,0) | D22: =VLOOKUP(B22,Veriler!A:B,2,0)

Sheet D-2
B1: # | C1: =VLOOKUP(A3,'Soru Listesi'!A:F,6,0)
A2: SORU ID | C2: TESPİT | D2: İDEAL DURUM | E2: PUAN DAĞILIMI
A3: D6.1 | B3: =VLOOKUP(A3,'Soru Listesi'!A:G,3,0) | C3: =VLOOKUP(A3,Veriler!A:D,4,0) | D3: =VLOOKUP(A3,'Soru Listesi'!A:G,5,0)
A4: D7.1 | B4: =VLOOKUP(A4,'Soru Listesi'!A:G,3,0) | C4: =VLOOKUP(A4,Veriler!A:D,4,0) | D4: =VLOOKUP(A4,'Soru Listesi'!A:G,5,0)
A5: D8.1 | B5: =VLOOKUP(A5,'Soru Listesi'!A:G,3,0) | C5: =VLOOKUP(A5,Veriler!A:D,4,0) | D5: =VLOOKUP(A5,'Soru Listesi'!A:G,5,0)
A6: D9.1 | B6: =VLOOKUP(A6,'Soru Listesi'!A:G,3,0) | C6: =VLOOKUP(A6,Veriler!A:D,4,0) | D6: =VLOOKUP(A6,'Soru Listesi'!A:G,5,0)
A7: D10.1 | B7: =VLOOKUP(A7,'Soru Listesi'!A:G,3,0) | C7: =VLOOKUP(A7,Veriler!A:D,4,0) | D7: =VLOOKUP(A7,'Soru Listesi'!A:G,5,0)
B10: ID | C10: KONU | D10: PUAN
B11: D1.1 | C11: =VLOOKUP(B11,'Soru Listesi'!A:C,3,0) | D11: =VLOOKUP(B11,Veriler!A:B,2,0)
B12: D2.1 | C12: =VLOOKUP(B12,'Soru Listesi'!A:C,3,0) | D12: =VLOOKUP(B12,Veriler!A:B,2,0)
B13: D3.1 | C13: =VLOOKUP(B13,'Soru Listesi'!A:C,3,0) | D13: =VLOOKUP(B13,Veriler!A:B,2,0)
B14: D4.1 | C14: =VLOOKUP(B14,'Soru Listesi'!A:C,3,0) | D14: =VLOOKUP(B14,Veriler!A:B,2,0)
B15: D5.1 | C15: =VLOOKUP(B15,'Soru Listesi'!A:C,3,0) | D15: =VLOOKUP(B15,Veriler!A:B,2,0)
B16: D6.1 | C16: =VLOOKUP(B16,'Soru Listesi'!A:C,3,0) | D16: =VLOOKUP(B16,Veriler!A:B,2,0)
B17: D7.1 | C17: =VLOOKUP(B17,'Soru Listesi'!A:C,3,0) | D17: =VLOOKUP(B17,Veriler!A:B,2,0)
B18: D8.1 | C18: =VLOOKUP(B18,'Soru Listesi'!A:C,3,0) | D18: =VLOOKUP(B18,Veriler!A:B,2,0)
B19: D9.1 | C19: =VLOOKUP(B19,'Soru Listesi'!A:C,3,0) | D19: =VLOOKUP(B19,Veriler!A:B,2,0)
B20: D10.1 | C20: =VLOOKUP(B20,'Soru Listesi'!A:C,3,0) | D20: =VLOOKUP(B20,Veriler!A:B,2,0)
B21: D11.1 | C21: =VLOOKUP(B21,'Soru Listesi'!A:C,3,0) | D21: =VLOOKUP(B21,Veriler!A:B,2,0)
B22: D12.1 | C22: =VLOOKUP(B22,'Soru Listesi'!A:C,3,0) | D22: =VLOOKUP(B22,Veriler!A:B,2,0)

Sheet D-3
B1: # | C1: =VLOOKUP(A3,'Soru Listesi'!A:F,6,0)
A2: SORU ID | C2: TESPİT | D2: İDEAL DURUM | E2: PUAN DAĞILIMI
A3: D11.1 | B3: =VLOOKUP(A3,'Soru Listesi'!A:G,3,0) | C3: =VLOOKUP(A3,Veriler!A:D,4,0) | D3: =VLOOKUP(A3,'Soru Listesi'!A:G,5,0)
A4: D12.1 | B4: =VLOOKUP(A4,'Soru Listesi'!A:G,3,0) | C4: =VLOOKUP(A4,Veriler!A:D,4,0) | D4: =VLOOKUP(A4,'Soru Listesi'!A:G,5,0)
B10: ID | C10: KONU | D10: PUAN
B11: D1.1 | C11: =VLOOKUP(B11,'Soru Listesi'!A:C,3,0) | D11: =VLOOKUP(B11,Veriler!A:B,2,0)
B12: D2.1 | C12: =VLOOKUP(B12,'Soru Listesi'!A:C,3,0) | D12: =VLOOKUP(B12,Veriler!A:B,2,0)
B13: D3.1 | C13: =VLOOKUP(B13,'Soru Listesi'!A:C,3,0) | D13: =VLOOKUP(B13,Veriler!A:B,2,0)
B14: D4.1 | C14: =VLOOKUP(B14,'Soru Listesi'!A:C,3,0) | D14: =VLOOKUP(B14,Veriler!A:B,2,0)
B15: D5.1 | C15: =VLOOKUP(B15,'Soru Listesi'!A:C,3,0) | D15: =VLOOKUP(B15,Veriler!A:B,2,0)
B16: D6.1 | C16: =VLOOKUP(B16,'Soru Listesi'!A:C,3,0) | D16: =VLOOKUP(B16,Veriler!A:B,2,0)
B17: D7.1 | C17: =VLOOKUP(B17,'Soru Listesi'!A:C,3,0) | D17: =VLOOKUP(B17,Veriler!A:B,2,0)
B18: D8.1 | C18: =VLOOKUP(B18,'Soru Listesi'!A:C,3,0) | D18: =VLOOKUP(B18,Veriler!A:B,2,0)
B19: D9.1 | C19: =VLOOKUP(B19,'Soru Listesi'!A:C,3,0) | D19: =VLOOKUP(B19,Veriler!A:B,2,0)
B20: D10.1 | C20: =VLOOKUP(B20,'Soru Listesi'!A:C,3,0) | D20: =VLOOKUP(B20,Veriler!A:B,2,0)
B21: D11.1 | C21: =VLOOKUP(B21,'Soru Listesi'!A:C,3,0) | D21: =VLOOKUP(B21,Veriler!A:B,2,0)
B22: D12.1 | C22: =VLOOKUP(B22,'Soru Listesi'!A:C,3,0) | D22: =VLOOKUP(B22,Veriler!A:B,2,0)

Sheet E-0
C2: =(CODE(UPPER(MID(CELL("dosyaadı",A1),FIND("]",CELL("dosyaadı",A1),1)+1,1)))-CODE("A")+1) & " - " &VLOOKUP(MID(CELL("dosyaadı",A1),FIND("]",CELL("dosyaadı",A1),1)+1,1),'Soru Listesi'!B:F,5,0)

Sheet E-1
B1: # | C1: =VLOOKUP(A3,'Soru Listesi'!A:F,6,0)
A2: SORU ID | C2: TESPİT | D2: İDEAL DURUM | E2: PUAN DAĞILIMI
A3: E1.1 | B3: =VLOOKUP(A3,'Soru Listesi'!A:G,3,0) | C3: =VLOOKUP(A3,Veriler!A:D,4,0) | D3: =VLOOKUP(A3,'Soru Listesi'!A:G,5,0)
A4: E2.1 | B4: =VLOOKUP(A4,'Soru Listesi'!A:G,3,0) | C4: =VLOOKUP(A4,Veriler!A:D,4,0) | D4: =VLOOKUP(A4,'Soru Listesi'!A:G,5,0)
A5: E3.1 | B5: =VLOOKUP(A5,'Soru Listesi'!A:G,3,0) | C5: =VLOOKUP(A5,Veriler!A:D,4,0) | D5: =VLOOKUP(A5,'Soru Listesi'!A:G,5,0)
A6: E4.1 | B6: =VLOOKUP(A6,'Soru Listesi'!A:G,3,0) | C6: =VLOOKUP(A6,Veriler!A:D,4,0) | D6: =VLOOKUP(A6,'Soru Listesi'!A:G,5,0)
A7: E4.2 | B7: =VLOOKUP(A7,'Soru Listesi'!A:G,3,0) | C7: =VLOOKUP(A7,Veriler!A:D,4,0) | D7: =VLOOKUP(A7,'Soru Listesi'!A:G,5,0)
B10: ID | C10: KONU | D10: PUAN
B11: E1.1 | C11: =VLOOKUP(B11,'Soru Listesi'!A:C,3,0) | D11: =VLOOKUP(B11,Veriler!A:B,2,0)
B12: E2.1 | C12: =VLOOKUP(B12,'Soru Listesi'!A:C,3,0) | D12: =VLOOKUP(B12,Veriler!A:B,2,0)
B13: E3.1 | C13: =VLOOKUP(B13,'Soru Listesi'!A:C,3,0) | D13: =VLOOKUP(B13,Veriler!A:B,2,0)
B14: E4.1 | C14: =VLOOKUP(B14,'Soru Listesi'!A:C,3,0) | D14: =VLOOKUP(B14,Veriler!A:B,2,0)
B15: E4.2 | C15: =VLOOKUP(B15,'Soru Listesi'!A:C,3,0) | D15: =VLOOKUP(B15,Veriler!A:B,2,0)
B16: E5.1 | C16: =VLOOKUP(B16,'Soru Listesi'!A:C,3,0) | D16: =VLOOKUP(B16,Veriler!A:B,2,0)
B17: E6.1 | C17: =VLOOKUP(B17,'Soru Listesi'!A:C,3,0) | D17: =VLOOKUP(B17,Veriler!A:B,2,0)
B18: E7.1 | C18: =VLOOKUP(B18,'Soru Listesi'!A:C,3,0) | D18: =VLOOKUP(B18,Veriler!A:B,2,0)
B19: E8.1 | C19: =VLOOKUP(B19,'Soru Listesi'!A:C,3,0) | D19: =VLOOKUP(B19,Veriler!A:B,2,0)

Sheet E-2
B1: # | C1: =VLOOKUP(A3,'Soru Listesi'!A:F,6,0)
A2: SORU ID | C2: TESPİT | D2: İDEAL DURUM | E2: PUAN DAĞILIMI
A3: E5.1 | B3: =VLOOKUP(A3,'Soru Listesi'!A:G,3,0) | C3: =VLOOKUP(A3,Veriler!A:D,4,0) | D3: =VLOOKUP(A3,'Soru Listesi'!A:G,5,0)
A4: E6.1 | B4: =VLOOKUP(A4,'Soru Listesi'!A:G,3,0) | C4: =VLOOKUP(A4,Veriler!A:D,4,0) | D4: =VLOOKUP(A4,'Soru Listesi'!A:G,5,0)
A5: E7.1 | B5: =VLOOKUP(A5,'Soru Listesi'!A:G,3,0) | C5: =VLOOKUP(A5,Veriler!A:D,4,0) | D5: =VLOOKUP(A5,'Soru Listesi'!A:G,5,0)
A6: E8.1 | B6: =VLOOKUP(A6,'Soru Listesi'!A:G,3,0) | C6: =VLOOKUP(A6,Veriler!A:D,4,0) | D6: =VLOOKUP(A6,'Soru Listesi'!A:G,5,0)
B10: ID | C10: KONU | D10: PUAN
B11: E1.1 | C11: =VLOOKUP(B11,'Soru Listesi'!A:C,3,0) | D11: =VLOOKUP(B11,Veriler!A:B,2,0)
B12: E2.1 | C12: =VLOOKUP(B12,'Soru Listesi'!A:C,3,0) | D12: =VLOOKUP(B12,Veriler!A:B,2,0)
B13: E3.1 | C13: =VLOOKUP(B13,'Soru Listesi'!A:C,3,0) | D13: =VLOOKUP(B13,Veriler!A:B,2,0)
B14: E4.1 | C14: =VLOOKUP(B14,'Soru Listesi'!A:C,3,0) | D14: =VLOOKUP(B14,Veriler!A:B,2,0)
B15: E4.2 | C15: =VLOOKUP(B15,'Soru Listesi'!A:C,3,0) | D15: =VLOOKUP(B15,Veriler!A:B,2,0)
B16: E5.1 | C16: =VLOOKUP(B16,'Soru Listesi'!A:C,3,0) | D16: =VLOOKUP(B16,Veriler!A:B,2,0)
B17: E6.1 | C17: =VLOOKUP(B17,'Soru Listesi'!A:C,3,0) | D17: =VLOOKUP(B17,Veriler!A:B,2,0)
B18: E7.1 | C18: =VLOOKUP(B18,'Soru Listesi'!A:C,3,0) | D18: =VLOOKUP(B18,Veriler!A:B,2,0)
B19: E8.1 | C19: =VLOOKUP(B19,'Soru Listesi'!A:C,3,0) | D19: =VLOOKUP(B19,Veriler!A:B,2,0)

Sheet F-0
C2: =(CODE(UPPER(MID(CELL("dosyaadı",A1),FIND("]",CELL("dosyaadı",A1),1)+1,1)))-CODE("A")+1) & " - " &VLOOKUP(MID(CELL("dosyaadı",A1),FIND("]",CELL("dosyaadı",A1),1)+1,1),'Soru Listesi'!B:F,5,0)

Sheet F-1
B1: # | C1: =VLOOKUP(A3,'Soru Listesi'!A:F,6,0)
A2: SORU ID | C2: TESPİT | D2: İDEAL DURUM | E2: PUAN DAĞILIMI
A3: F1.1 | B3: =VLOOKUP(A3,'Soru Listesi'!A:G,3,0) | C3: =VLOOKUP(A3,Veriler!A:D,4,0) | D3: =VLOOKUP(A3,'Soru Listesi'!A:G,5,0)
A4: F2.1 | B4: =VLOOKUP(A4,'Soru Listesi'!A:G,3,0) | C4: =VLOOKUP(A4,Veriler!A:D,4,0) | D4: =VLOOKUP(A4,'Soru Listesi'!A:G,5,0)
A5: F3.1 | B5: =VLOOKUP(A5,'Soru Listesi'!A:G,3,0) | C5: =VLOOKUP(A5,Veriler!A:D,4,0) | D5: =VLOOKUP(A5,'Soru Listesi'!A:G,5,0)
A6: F4.1 | B6: =VLOOKUP(A6,'Soru Listesi'!A:G,3,0) | C6: =VLOOKUP(A6,Veriler!A:D,4,0) | D6: =VLOOKUP(A6,'Soru Listesi'!A:G,5,0)
A7: F5.1 | B7: =VLOOKUP(A7,'Soru Listesi'!A:G,3,0) | C7: =VLOOKUP(A7,Veriler!A:D,4,0) | D7: =VLOOKUP(A7,'Soru Listesi'!A:G,5,0)
B10: ID | C10: KONU | D10: PUAN
B11: F1.1 | C11: =VLOOKUP(B11,'Soru Listesi'!A:C,3,0) | D11: =VLOOKUP(B11,Veriler!A:B,2,0)
B12: F2.1 | C12: =VLOOKUP(B12,'Soru Listesi'!A:C,3,0) | D12: =VLOOKUP(B12,Veriler!A:B,2,0)
B13: F3.1 | C13: =VLOOKUP(B13,'Soru Listesi'!A:C,3,0) | D13: =VLOOKUP(B13,Veriler!A:B,2,0)
B14: F4.1 | C14: =VLOOKUP(B14,'Soru Listesi'!A:C,3,0) | D14: =VLOOKUP(B14,Veriler!A:B,2,0)
B15: F5.1 | C15: =VLOOKUP(B15,'Soru Listesi'!A:C,3,0) | D15: =VLOOKUP(B15,Veriler!A:B,2,0)
B16: F6.1 | C16: =VLOOKUP(B16,'Soru Listesi'!A:C,3,0) | D16: =VLOOKUP(B16,Veriler!A:B,2,0)
B17: F7.1 | C17: =VLOOKUP(B17,'Soru Listesi'!A:C,3,0) | D17: =VLOOKUP(B17,Veriler!A:B,2,0)
B18: F8.1 | C18: =VLOOKUP(B18,'Soru Listesi'!A:C,3,0) | D18: =VLOOKUP(B18,Veriler!A:B,2,0)

Sheet F-2
B1: # | C1: =VLOOKUP(A3,'Soru Listesi'!A:F,6,0)
A2: SORU ID | C2: TESPİT | D2: İDEAL DURUM | E2: PUAN DAĞILIMI
A3: F6.1 | B3: =VLOOKUP(A3,'Soru Listesi'!A:G,3,0) | C3: =VLOOKUP(A3,Veriler!A:D,4,0) | D3: =VLOOKUP(A3,'Soru Listesi'!A:G,5,0)
A4: F7.1 | B4: =VLOOKUP(A4,'Soru Listesi'!A:G,3,0) | C4: =VLOOKUP(A4,Veriler!A:D,4,0) | D4: =VLOOKUP(A4,'Soru Listesi'!A:G,5,0)
A5: F8.1 | B5: =VLOOKUP(A5,'Soru Listesi'!A:G,3,0) | C5: =VLOOKUP(A5,Veriler!A:D,4,0) | D5: =VLOOKUP(A5,'Soru Listesi'!A:G,5,0)
B10: ID | C10: KONU | D10: PUAN
B11: F1.1 | C11: =VLOOKUP(B11,'Soru Listesi'!A:C,3,0) | D11: =VLOOKUP(B11,Veriler!A:B,2,0)
B12: F2.1 | C12: =VLOOKUP(B12,'Soru Listesi'!A:C,3,0) | D12: =VLOOKUP(B12,Veriler!A:B,2,0)
B13: F3.1 | C13: =VLOOKUP(B13,'Soru Listesi'!A:C,3,0) | D13: =VLOOKUP(B13,Veriler!A:B,2,0)
B14: F4.1 | C14: =VLOOKUP(B14,'Soru Listesi'!A:C,3,0) | D14: =VLOOKUP(B14,Veriler!A:B,2,0)
B15: F5.1 | C15: =VLOOKUP(B15,'Soru Listesi'!A:C,3,0) | D15: =VLOOKUP(B15,Veriler!A:B,2,0)
B16: F6.1 | C16: =VLOOKUP(B16,'Soru Listesi'!A:C,3,0) | D16: =VLOOKUP(B16,Veriler!A:B,2,0)
B17: F7.1 | C17: =VLOOKUP(B17,'Soru Listesi'!A:C,3,0) | D17: =VLOOKUP(B17,Veriler!A:B,2,0)
B18: F8.1 | C18: =VLOOKUP(B18,'Soru Listesi'!A:C,3,0) | D18: =VLOOKUP(B18,Veriler!A:B,2,0)

Sheet G-0
C2: =(CODE(UPPER(MID(CELL("dosyaadı",A1),FIND("]",CELL("dosyaadı",A1),1)+1,1)))-CODE("A")+1) & " - " &VLOOKUP(MID(CELL("dosyaadı",A1),FIND("]",CELL("dosyaadı",A1),1)+1,1),'Soru Listesi'!B:F,5,0)

Sheet G-1
B1: # | C1: =VLOOKUP(A3,'Soru Listesi'!A:F,6,0)
A2: SORU ID | C2: TESPİT | D2: İDEAL DURUM | E2: PUAN DAĞILIMI
A3: G1.1 | B3: =VLOOKUP(A3,'Soru Listesi'!A:G,3,0) | C3: =VLOOKUP(A3,Veriler!A:D,4,0) | D3: =VLOOKUP(A3,'Soru Listesi'!A:G,5,0)
A4: G2.1 | B4: =VLOOKUP(A4,'Soru Listesi'!A:G,3,0) | C4: =VLOOKUP(A4,Veriler!A:D,4,0) | D4: =VLOOKUP(A4,'Soru Listesi'!A:G,5,0)
A5: G3.1 | B5: =VLOOKUP(A5,'Soru Listesi'!A:G,3,0) | C5: =VLOOKUP(A5,Veriler!A:D,4,0) | D5: =VLOOKUP(A5,'Soru Listesi'!A:G,5,0)
A6: G4.1 | B6: =VLOOKUP(A6,'Soru Listesi'!A:G,3,0) | C6: =VLOOKUP(A6,Veriler!A:D,4,0) | D6: =VLOOKUP(A6,'Soru Listesi'!A:G,5,0)
A7: G5.1 | B7: =VLOOKUP(A7,'Soru Listesi'!A:G,3,0) | C7: =VLOOKUP(A7,Veriler!A:D,4,0) | D7: =VLOOKUP(A7,'Soru Listesi'!A:G,5,0)
B10: ID | C10: KONU | D10: PUAN
B11: G1.1 | C11: =VLOOKUP(B11,'Soru Listesi'!A:C,3,0) | D11: =VLOOKUP(B11,Veriler!A:B,2,0)
B12: G2.1 | C12: =VLOOKUP(B12,'Soru Listesi'!A:C,3,0) | D12: =VLOOKUP(B12,Veriler!A:B,2,0)
B13: G3.1 | C13: =VLOOKUP(B13,'Soru Listesi'!A:C,3,0) | D13: =VLOOKUP(B13,Veriler!A:B,2,0)
B14: G4.1 | C14: =VLOOKUP(B14,'Soru Listesi'!A:C,3,0) | D14: =VLOOKUP(B14,Veriler!A:B,2,0)
B15: G5.1 | C15: =VLOOKUP(B15,'Soru Listesi'!A:C,3,0) | D15: =VLOOKUP(B15,Veriler!A:B,2,0)
B16: G6.1 | C16: =VLOOKUP(B16,'Soru Listesi'!A:C,3,0) | D16: =VLOOKUP(B16,Veriler!A:B,2,0)
B17: G7.1 | C17: =VLOOKUP(B17,'Soru Listesi'!A:C,3,0) | D17: =VLOOKUP(B17,Veriler!A:B,2,0)
B18: G8.1 | C18: =VLOOKUP(B18,'Soru Listesi'!A:C,3,0) | D18: =VLOOKUP(B18,Veriler!A:B,2,0)

Sheet G-2
B1: # | C1: =VLOOKUP(A3,'Soru Listesi'!A:F,6,0)
A2: SORU ID | C2: TESPİT | D2: İDEAL DURUM | E2: PUAN DAĞILIMI
A3: G6.1 | B3: =VLOOKUP(A3,'Soru Listesi'!A:G,3,0) | C3: =VLOOKUP(A3,Veriler!A:D,4,0) | D3: =VLOOKUP(A3,'Soru Listesi'!A:G,5,0)
A4: G7.1 | B4: =VLOOKUP(A4,'Soru Listesi'!A:G,3,0) | C4: =VLOOKUP(A4,Veriler!A:D,4,0) | D4: =VLOOKUP(A4,'Soru Listesi'!A:G,5,0)
A5: G8.1 | B5: =VLOOKUP(A5,'Soru Listesi'!A:G,3,0) | C5: =VLOOKUP(A5,Veriler!A:D,4,0) | D5: =VLOOKUP(A5,'Soru Listesi'!A:G,5,0)
B10: ID | C10: KONU | D10: PUAN
B11: G1.1 | C11: =VLOOKUP(B11,'Soru Listesi'!A:C,3,0) | D11: =VLOOKUP(B11,Veriler!A:B,2,0)
B12: G2.1 | C12: =VLOOKUP(B12,'Soru Listesi'!A:C,3,0) | D12: =VLOOKUP(B12,Veriler!A:B,2,0)
B13: G3.1 | C13: =VLOOKUP(B13,'Soru Listesi'!A:C,3,0) | D13: =VLOOKUP(B13,Veriler!A:B,2,0)
B14: G4.1 | C14: =VLOOKUP(B14,'Soru Listesi'!A:C,3,0) | D14: =VLOOKUP(B14,Veriler!A:B,2,0)
B15: G5.1 | C15: =VLOOKUP(B15,'Soru Listesi'!A:C,3,0) | D15: =VLOOKUP(B15,Veriler!A:B,2,0)
B16: G6.1 | C16: =VLOOKUP(B16,'Soru Listesi'!A:C,3,0) | D16: =VLOOKUP(B16,Veriler!A:B,2,0)
B17: G7.1 | C17: =VLOOKUP(B17,'Soru Listesi'!A:C,3,0) | D17: =VLOOKUP(B17,Veriler!A:B,2,0)
B18: G8.1 | C18: =VLOOKUP(B18,'Soru Listesi'!A:C,3,0) | D18: =VLOOKUP(B18,Veriler!A:B,2,0)

Sheet H-0
C2: =(CODE(UPPER(MID(CELL("dosyaadı",A1),FIND("]",CELL("dosyaadı",A1),1)+1,1)))-CODE("A")+1) & " - " &VLOOKUP(MID(CELL("dosyaadı",A1),FIND("]",CELL("dosyaadı",A1),1)+1,1),'Soru Listesi'!B:F,5,0)

Sheet H-1
B1: # | C1: =VLOOKUP(A3,'Soru Listesi'!A:F,6,0)
A2: SORU ID | C2: TESPİT | D2: İDEAL DURUM | E2: PUAN DAĞILIMI
A3: H1.1 | B3: =VLOOKUP(A3,'Soru Listesi'!A:G,3,0) | C3: =VLOOKUP(A3,Veriler!A:D,4,0) | D3: =VLOOKUP(A3,'Soru Listesi'!A:G,5,0)
A4: H2.1 | B4: =VLOOKUP(A4,'Soru Listesi'!A:G,3,0) | C4: =VLOOKUP(A4,Veriler!A:D,4,0) | D4: =VLOOKUP(A4,'Soru Listesi'!A:G,5,0)
A5: H3.1 | B5: =VLOOKUP(A5,'Soru Listesi'!A:G,3,0) | C5: =VLOOKUP(A5,Veriler!A:D,4,0) | D5: =VLOOKUP(A5,'Soru Listesi'!A:G,5,0)
A6: H4.1 | B6: =VLOOKUP(A6,'Soru Listesi'!A:G,3,0) | C6: =VLOOKUP(A6,Veriler!A:D,4,0) | D6: =VLOOKUP(A6,'Soru Listesi'!A:G,5,0)
A7: H4.2 | B7: =VLOOKUP(A7,'Soru Listesi'!A:G,3,0) | C7: =VLOOKUP(A7,Veriler!A:D,4,0) | D7: =VLOOKUP(A7,'Soru Listesi'!A:G,5,0)
B10: ID | C10: KONU | D10: PUAN
B11: H1.1 | C11: =VLOOKUP(B11,'Soru Listesi'!A:C,3,0) | D11: =VLOOKUP(B11,Veriler!A:B,2,0)
B12: H2.1 | C12: =VLOOKUP(B12,'Soru Listesi'!A:C,3,0) | D12: =VLOOKUP(B12,Veriler!A:B,2,0)
B13: H3.1 | C13: =VLOOKUP(B13,'Soru Listesi'!A:C,3,0) | D13: =VLOOKUP(B13,Veriler!A:B,2,0)
B14: H4.1 | C14: =VLOOKUP(B14,'Soru Listesi'!A:C,3,0) | D14: =VLOOKUP(B14,Veriler!A:B,2,0)
B15: H4.2 | C15: =VLOOKUP(B15,'Soru Listesi'!A:C,3,0) | D15: =VLOOKUP(B15,Veriler!A:B,2,0)
B16: H5.1 | C16: =VLOOKUP(B16,'Soru Listesi'!A:C,3,0) | D16: =VLOOKUP(B16,Veriler!A:B,2,0)
B17: H6.1 | C17: =VLOOKUP(B17,'Soru Listesi'!A:C,3,0) | D17: =VLOOKUP(B17,Veriler!A:B,2,0)
B18: H7.1 | C18: =VLOOKUP(B18,'Soru Listesi'!A:C,3,0) | D18: =VLOOKUP(B18,Veriler!A:B,2,0)
B19: H8.1 | C19: =VLOOKUP(B19,'Soru Listesi'!A:C,3,0) | D19: =VLOOKUP(B19,Veriler!A:B,2,0)
B20: H9.1 | C20: =VLOOKUP(B20,'Soru Listesi'!A:C,3,0) | D20: =VLOOKUP(B20,Veriler!A:B,2,0)
B21: H10.1 | C21: =VLOOKUP(B21,'Soru Listesi'!A:C,3,0) | D21: =VLOOKUP(B21,Veriler!A:B,2,0)
B22: H10.2 | C22: =VLOOKUP(B22,'Soru Listesi'!A:C,3,0) | D22: =VLOOKUP(B22,Veriler!A:B,2,0)
B23: H11.1 | C23: =VLOOKUP(B23,'Soru Listesi'!A:C,3,0) | D23: =VLOOKUP(B23,Veriler!A:B,2,0)

Sheet H-2
B1: # | C1: =VLOOKUP(A3,'Soru Listesi'!A:F,6,0)
A2: SORU ID | C2: TESPİT | D2: İDEAL DURUM | E2: PUAN DAĞILIMI
A3: H5.1 | B3: =VLOOKUP(A3,'Soru Listesi'!A:G,3,0) | C3: =VLOOKUP(A3,Veriler!A:D,4,0) | D3: =VLOOKUP(A3,'Soru Listesi'!A:G,5,0)
A4: H6.1 | B4: =VLOOKUP(A4,'Soru Listesi'!A:G,3,0) | C4: =VLOOKUP(A4,Veriler!A:D,4,0) | D4: =VLOOKUP(A4,'Soru Listesi'!A:G,5,0)
A5: H7.1 | B5: =VLOOKUP(A5,'Soru Listesi'!A:G,3,0) | C5: =VLOOKUP(A5,Veriler!A:D,4,0) | D5: =VLOOKUP(A5,'Soru Listesi'!A:G,5,0)
A6: H8.1 | B6: =VLOOKUP(A6,'Soru Listesi'!A:G,3,0) | C6: =VLOOKUP(A6,Veriler!A:D,4,0) | D6: =VLOOKUP(A6,'Soru Listesi'!A:G,5,0)
A7: H9.1 | B7: =VLOOKUP(A7,'Soru Listesi'!A:G,3,0) | C7: =VLOOKUP(A7,Veriler!A:D,4,0) | D7: =VLOOKUP(A7,'Soru Listesi'!A:G,5,0)
B10: ID | C10: KONU | D10: PUAN
B11: H1.1 | C11: =VLOOKUP(B11,'Soru Listesi'!A:C,3,0) | D11: =VLOOKUP(B11,Veriler!A:B,2,0)
B12: H2.1 | C12: =VLOOKUP(B12,'Soru Listesi'!A:C,3,0) | D12: =VLOOKUP(B12,Veriler!A:B,2,0)
B13: H3.1 | C13: =VLOOKUP(B13,'Soru Listesi'!A:C,3,0) | D13: =VLOOKUP(B13,Veriler!A:B,2,0)
B14: H4.1 | C14: =VLOOKUP(B14,'Soru Listesi'!A:C,3,0) | D14: =VLOOKUP(B14,Veriler!A:B,2,0)
B15: H4.2 | C15: =VLOOKUP(B15,'Soru Listesi'!A:C,3,0) | D15: =VLOOKUP(B15,Veriler!A:B,2,0)
B16: H5.1 | C16: =VLOOKUP(B16,'Soru Listesi'!A:C,3,0) | D16: =VLOOKUP(B16,Veriler!A:B,2,0)
B17: H6.1 | C17: =VLOOKUP(B17,'Soru Listesi'!A:C,3,0) | D17: =VLOOKUP(B17,Veriler!A:B,2,0)
B18: H7.1 | C18: =VLOOKUP(B18,'Soru Listesi'!A:C,3,0) | D18: =VLOOKUP(B18,Veriler!A:B,2,0)
B19: H8.1 | C19: =VLOOKUP(B19,'Soru Listesi'!A:C,3,0) | D19: =VLOOKUP(B19,Veriler!A:B,2,0)
B20: H9.1 | C20: =VLOOKUP(B20,'Soru Listesi'!A:C,3,0) | D20: =VLOOKUP(B20,Veriler!A:B,2,0)
B21: H10.1 | C21: =VLOOKUP(B21,'Soru Listesi'!A:C,3,0) | D21: =VLOOKUP(B21,Veriler!A:B,2,0)
B22: H10.2 | C22: =VLOOKUP(B22,'Soru Listesi'!A:C,3,0) | D22: =VLOOKUP(B22,Veriler!A:B,2,0)
B23: H11.1 | C23: =VLOOKUP(B23,'Soru Listesi'!A:C,3,0) | D23: =VLOOKUP(B23,Veriler!A:B,2,0)

Sheet H-3
B1: # | C1: =VLOOKUP(A3,'Soru Listesi'!A:F,6,0)
A2: SORU ID | C2: TESPİT | D2: İDEAL DURUM | E2: PUAN DAĞILIMI
A3: H10.1 | B3: =VLOOKUP(A3,'Soru Listesi'!A:G,3,0) | C3: =VLOOKUP(A3,Veriler!A:D,4,0) | D3: =VLOOKUP(A3,'Soru Listesi'!A:G,5,0)
A4: H10.2 | B4: =VLOOKUP(A4,'Soru Listesi'!A:G,3,0) | C4: =VLOOKUP(A4,Veriler!A:D,4,0) | D4: =VLOOKUP(A4,'Soru Listesi'!A:G,5,0)
A5: H11.1 | B5: =VLOOKUP(A5,'Soru Listesi'!A:G,3,0) | C5: =VLOOKUP(A5,Veriler!A:D,4,0) | D5: =VLOOKUP(A5,'Soru Listesi'!A:G,5,0)
B10: ID | C10: KONU | D10: PUAN
B11: H1.1 | C11: =VLOOKUP(B11,'Soru Listesi'!A:C,3,0) | D11: =VLOOKUP(B11,Veriler!A:B,2,0)
B12: H2.1 | C12: =VLOOKUP(B12,'Soru Listesi'!A:C,3,0) | D12: =VLOOKUP(B12,Veriler!A:B,2,0)
B13: H3.1 | C13: =VLOOKUP(B13,'Soru Listesi'!A:C,3,0) | D13: =VLOOKUP(B13,Veriler!A:B,2,0)
B14: H4.1 | C14: =VLOOKUP(B14,'Soru Listesi'!A:C,3,0) | D14: =VLOOKUP(B14,Veriler!A:B,2,0)
B15: H4.2 | C15: =VLOOKUP(B15,'Soru Listesi'!A:C,3,0) | D15: =VLOOKUP(B15,Veriler!A:B,2,0)
B16: H5.1 | C16: =VLOOKUP(B16,'Soru Listesi'!A:C,3,0) | D16: =VLOOKUP(B16,Veriler!A:B,2,0)
B17: H6.1 | C17: =VLOOKUP(B17,'Soru Listesi'!A:C,3,0) | D17: =VLOOKUP(B17,Veriler!A:B,2,0)
B18: H7.1 | C18: =VLOOKUP(B18,'Soru Listesi'!A:C,3,0) | D18: =VLOOKUP(B18,Veriler!A:B,2,0)
B19: H8.1 | C19: =VLOOKUP(B19,'Soru Listesi'!A:C,3,0) | D19: =VLOOKUP(B19,Veriler!A:B,2,0)
B20: H9.1 | C20: =VLOOKUP(B20,'Soru Listesi'!A:C,3,0) | D20: =VLOOKUP(B20,Veriler!A:B,2,0)
B21: H10.1 | C21: =VLOOKUP(B21,'Soru Listesi'!A:C,3,0) | D21: =VLOOKUP(B21,Veriler!A:B,2,0)
B22: H10.2 | C22: =VLOOKUP(B22,'Soru Listesi'!A:C,3,0) | D22: =VLOOKUP(B22,Veriler!A:B,2,0)
B23: H11.1 | C23: =VLOOKUP(B23,'Soru Listesi'!A:C,3,0) | D23: =VLOOKUP(B23,Veriler!A:B,2,0)

Sheet I-0
C2: =(CODE(UPPER(MID(CELL("dosyaadı",A1),FIND("]",CELL("dosyaadı",A1),1)+1,1)))-CODE("A")+1) & " - " &VLOOKUP(MID(CELL("dosyaadı",A1),FIND("]",CELL("dosyaadı",A1),1)+1,1),'Soru Listesi'!B:F,5,0)

Sheet I-1
B1: # | C1: =VLOOKUP(A3,'Soru Listesi'!A:F,6,0)
A2: SORU ID | C2: TESPİT | D2: İDEAL DURUM | E2: PUAN DAĞILIMI
A3: I1.1 | B3: =VLOOKUP(A3,'Soru Listesi'!A:G,3,0) | C3: =VLOOKUP(A3,Veriler!A:D,4,0) | D3: =VLOOKUP(A3,'Soru Listesi'!A:G,5,0)
A4: I2.1 | B4: =VLOOKUP(A4,'Soru Listesi'!A:G,3,0) | C4: =VLOOKUP(A4,Veriler!A:D,4,0) | D4: =VLOOKUP(A4,'Soru Listesi'!A:G,5,0)
A5: I3.1 | B5: =VLOOKUP(A5,'Soru Listesi'!A:G,3,0) | C5: =VLOOKUP(A5,Veriler!A:D,4,0) | D5: =VLOOKUP(A5,'Soru Listesi'!A:G,5,0)
A6: I4.1 | B6: =VLOOKUP(A6,'Soru Listesi'!A:G,3,0) | C6: =VLOOKUP(A6,Veriler!A:D,4,0) | D6: =VLOOKUP(A6,'Soru Listesi'!A:G,5,0)
A7: I5.1 | B7: =VLOOKUP(A7,'Soru Listesi'!A:G,3,0) | C7: =VLOOKUP(A7,Veriler!A:D,4,0) | D7: =VLOOKUP(A7,'Soru Listesi'!A:G,5,0)
B10: ID | C10: KONU | D10: PUAN
B11: I1.1 | C11: =VLOOKUP(B11,'Soru Listesi'!A:C,3,0) | D11: =VLOOKUP(B11,Veriler!A:B,2,0)
B12: I2.1 | C12: =VLOOKUP(B12,'Soru Listesi'!A:C,3,0) | D12: =VLOOKUP(B12,Veriler!A:B,2,0)
B13: I3.1 | C13: =VLOOKUP(B13,'Soru Listesi'!A:C,3,0) | D13: =VLOOKUP(B13,Veriler!A:B,2,0)
B14: I4.1 | C14: =VLOOKUP(B14,'Soru Listesi'!A:C,3,0) | D14: =VLOOKUP(B14,Veriler!A:B,2,0)
B15: I5.1 | C15: =VLOOKUP(B15,'Soru Listesi'!A:C,3,0) | D15: =VLOOKUP(B15,Veriler!A:B,2,0)
B16: I6.1 | C16: =VLOOKUP(B16,'Soru Listesi'!A:C,3,0) | D16: =VLOOKUP(B16,Veriler!A:B,2,0)

Sheet I-2
B1: # | C1: =VLOOKUP(A3,'Soru Listesi'!A:F,6,0)
A2: SORU ID | C2: TESPİT | D2: İDEAL DURUM | E2: PUAN DAĞILIMI
A3: I6.1 | B3: =VLOOKUP(A3,'Soru Listesi'!A:G,3,0) | C3: =VLOOKUP(A3,Veriler!A:D,4,0) | D3: =VLOOKUP(A3,'Soru Listesi'!A:G,5,0)
A4: I7.1 | B4: =VLOOKUP(A4,'Soru Listesi'!A:G,3,0) | C4: =VLOOKUP(A4,Veriler!A:D,4,0) | D4: =VLOOKUP(A4,'Soru Listesi'!A:G,5,0)
B10: ID | C10: KONU | D10: PUAN
B11: I1.1 | C11: =VLOOKUP(B11,'Soru Listesi'!A:C,3,0) | D11: =VLOOKUP(B11,Veriler!A:B,2,0)
B12: I2.1 | C12: =VLOOKUP(B12,'Soru Listesi'!A:C,3,0) | D12: =VLOOKUP(B12,Veriler!A:B,2,0)
B13: I3.1 | C13: =VLOOKUP(B13,'Soru Listesi'!A:C,3,0) | D13: =VLOOKUP(B13,Veriler!A:B,2,0)
B14: I4.1 | C14: =VLOOKUP(B14,'Soru Listesi'!A:C,3,0) | D14: =VLOOKUP(B14,Veriler!A:B,2,0)
B15: I5.1 | C15: =VLOOKUP(B15,'Soru Listesi'!A:C,3,0) | D15: =VLOOKUP(B15,Veriler!A:B,2,0)
B16: I6.1 | C16: =VLOOKUP(B16,'Soru Listesi'!A:C,3,0) | D16: =VLOOKUP(B16,Veriler!A:B,2,0)
B17: I7.1 | C17: =VLOOKUP(B17,'Soru Listesi'!A:C,3,0) | D17: =VLOOKUP(B17,Veriler!A:B,2,0)

Sheet J-0
C2: =(CODE(UPPER(MID(CELL("dosyaadı",A1),FIND("]",CELL("dosyaadı",A1),1)+1,1)))-CODE("A")+1) & " - " &VLOOKUP(MID(CELL("dosyaadı",A1),FIND("]",CELL("dosyaadı",A1),1)+1,1),'Soru Listesi'!B:F,5,0)

Sheet J-1
B1: # | C1: =VLOOKUP(A3,'Soru Listesi'!A:F,6,0)
A2: SORU ID | C2: TESPİT | D2: İDEAL DURUM | E2: PUAN DAĞILIMI
A3: J1.1 | B3: =VLOOKUP(A3,'Soru Listesi'!A:G,3,0) | C3: =VLOOKUP(A3,Veriler!A:D,4,0) | D3: =VLOOKUP(A3,'Soru Listesi'!A:G,5,0)
A4: J2.1 | B4: =VLOOKUP(A4,'Soru Listesi'!A:G,3,0) | C4: =VLOOKUP(A4,Veriler!A:D,4,0) | D4: =VLOOKUP(A4,'Soru Listesi'!A:G,5,0)
A5: J2.2 | B5: =VLOOKUP(A5,'Soru Listesi'!A:G,3,0) | C5: =VLOOKUP(A5,Veriler!A:D,4,0) | D5: =VLOOKUP(A5,'Soru Listesi'!A:G,5,0)
A6: J3.1 | B6: =VLOOKUP(A6,'Soru Listesi'!A:G,3,0) | C6: =VLOOKUP(A6,Veriler!A:D,4,0) | D6: =VLOOKUP(A6,'Soru Listesi'!A:G,5,0)
A7: J4.1 | B7: =VLOOKUP(A7,'Soru Listesi'!A:G,3,0) | C7: =VLOOKUP(A7,Veriler!A:D,4,0) | D7: =VLOOKUP(A7,'Soru Listesi'!A:G,5,0)
B10: ID | C10: KONU | D10: PUAN
B11: J1.1 | C11: =VLOOKUP(B11,'Soru Listesi'!A:C,3,0) | D11: =VLOOKUP(B11,Veriler!A:B,2,0)
B12: J2.1 | C12: =VLOOKUP(B12,'Soru Listesi'!A:C,3,0) | D12: =VLOOKUP(B12,Veriler!A:B,2,0)
B13: J2.2 | C13: =VLOOKUP(B13,'Soru Listesi'!A:C,3,0) | D13: =VLOOKUP(B13,Veriler!A:B,2,0)
B14: J3.1 | C14: =VLOOKUP(B14,'Soru Listesi'!A:C,3,0) | D14: =VLOOKUP(B14,Veriler!A:B,2,0)
B15: J4.1 | C15: =VLOOKUP(B15,'Soru Listesi'!A:C,3,0) | D15: =VLOOKUP(B15,Veriler!A:B,2,0)
B16: J5.1 | C16: =VLOOKUP(B16,'Soru Listesi'!A:C,3,0) | D16: =VLOOKUP(B16,Veriler!A:B,2,0)
B17: J6.1 | C17: =VLOOKUP(B17,'Soru Listesi'!A:C,3,0) | D17: =VLOOKUP(B17,Veriler!A:B,2,0)
B18: J7.1 | C18: =VLOOKUP(B18,'Soru Listesi'!A:C,3,0) | D18: =VLOOKUP(B18,Veriler!A:B,2,0)
B19: J8.1 | C19: =VLOOKUP(B19,'Soru Listesi'!A:C,3,0) | D19: =VLOOKUP(B19,Veriler!A:B,2,0)

Sheet J-2
B1: # | C1: =VLOOKUP(A3,'Soru Listesi'!A:F,6,0)
A2: SORU ID | C2: TESPİT | D2: İDEAL DURUM | E2: PUAN DAĞILIMI
A3: J5.1 | B3: =VLOOKUP(A3,'Soru Listesi'!A:G,3,0) | C3: =VLOOKUP(A3,Veriler!A:D,4,0) | D3: =VLOOKUP(A3,'Soru Listesi'!A:G,5,0)
A4: J6.1 | B4: =VLOOKUP(A4,'Soru Listesi'!A:G,3,0) | C4: =VLOOKUP(A4,Veriler!A:D,4,0) | D4: =VLOOKUP(A4,'Soru Listesi'!A:G,5,0)
A5: J7.1 | B5: =VLOOKUP(A5,'Soru Listesi'!A:G,3,0) | C5: =VLOOKUP(A5,Veriler!A:D,4,0) | D5: =VLOOKUP(A5,'Soru Listesi'!A:G,5,0)
A6: J8.1 | B6: =VLOOKUP(A6,'Soru Listesi'!A:G,3,0) | C6: =VLOOKUP(A6,Veriler!A:D,4,0) | D6: =VLOOKUP(A6,'Soru Listesi'!A:G,5,0)
B10: ID | C10: KONU | D10: PUAN
B11: J1.1 | C11: =VLOOKUP(B11,'Soru Listesi'!A:C,3,0) | D11: =VLOOKUP(B11,Veriler!A:B,2,0)
B12: J2.1 | C12: =VLOOKUP(B12,'Soru Listesi'!A:C,3,0) | D12: =VLOOKUP(B12,Veriler!A:B,2,0)
B13: J2.2 | C13: =VLOOKUP(B13,'Soru Listesi'!A:C,3,0) | D13: =VLOOKUP(B13,Veriler!A:B,2,0)
B14: J3.1 | C14: =VLOOKUP(B14,'Soru Listesi'!A:C,3,0) | D14: =VLOOKUP(B14,Veriler!A:B,2,0)
B15: J4.1 | C15: =VLOOKUP(B15,'Soru Listesi'!A:C,3,0) | D15: =VLOOKUP(B15,Veriler!A:B,2,0)
B16: J5.1 | C16: =VLOOKUP(B16,'Soru Listesi'!A:C,3,0) | D16: =VLOOKUP(B16,Veriler!A:B,2,0)
B17: J6.1 | C17: =VLOOKUP(B17,'Soru Listesi'!A:C,3,0) | D17: =VLOOKUP(B17,Veriler!A:B,2,0)
B18: J7.1 | C18: =VLOOKUP(B18,'Soru Listesi'!A:C,3,0) | D18: =VLOOKUP(B18,Veriler!A:B,2,0)
B19: J8.1 | C19: =VLOOKUP(B19,'Soru Listesi'!A:C,3,0) | D19: =VLOOKUP(B19,Veriler!A:B,2,0)

Sheet K-0
C2: =(CODE(UPPER(MID(CELL("dosyaadı",A1),FIND("]",CELL("dosyaadı",A1),1)+1,1)))-CODE("A")+1) & " - " &VLOOKUP(MID(CELL("dosyaadı",A1),FIND("]",CELL("dosyaadı",A1),1)+1,1),'Soru Listesi'!B:F,5,0)

Sheet K-1
B1: # | C1: =VLOOKUP(A3,'Soru Listesi'!A:F,6,0)
A2: SORU ID | C2: TESPİT | D2: İDEAL DURUM | E2: PUAN DAĞILIMI
A3: K1.1 | B3: =VLOOKUP(A3,'Soru Listesi'!A:G,3,0) | C3: =VLOOKUP(A3,Veriler!A:D,4,0) | D3: =VLOOKUP(A3,'Soru Listesi'!A:G,5,0)
A4: K2.1 | B4: =VLOOKUP(A4,'Soru Listesi'!A:G,3,0) | C4: =VLOOKUP(A4,Veriler!A:D,4,0) | D4: =VLOOKUP(A4,'Soru Listesi'!A:G,5,0)
A5: K3.1 | B5: =VLOOKUP(A5,'Soru Listesi'!A:G,3,0) | C5: =VLOOKUP(A5,Veriler!A:D,4,0) | D5: =VLOOKUP(A5,'Soru Listesi'!A:G,5,0)
A6: K4.1 | B6: =VLOOKUP(A6,'Soru Listesi'!A:G,3,0) | C6: =VLOOKUP(A6,Veriler!A:D,4,0) | D6: =VLOOKUP(A6,'Soru Listesi'!A:G,5,0)
A7: K5.1 | B7: =VLOOKUP(A7,'Soru Listesi'!A:G,3,0) | C7: =VLOOKUP(A7,Veriler!A:D,4,0) | D7: =VLOOKUP(A7,'Soru Listesi'!A:G,5,0)
B10: ID | C10: KONU | D10: PUAN
B11: K1.1 | C11: =VLOOKUP(B11,'Soru Listesi'!A:C,3,0) | D11: =VLOOKUP(B11,Veriler!A:B,2,0)
B12: K2.1 | C12: =VLOOKUP(B12,'Soru Listesi'!A:C,3,0) | D12: =VLOOKUP(B12,Veriler!A:B,2,0)
B13: K3.1 | C13: =VLOOKUP(B13,'Soru Listesi'!A:C,3,0) | D13: =VLOOKUP(B13,Veriler!A:B,2,0)
B14: K4.1 | C14: =VLOOKUP(B14,'Soru Listesi'!A:C,3,0) | D14: =VLOOKUP(B14,Veriler!A:B,2,0)
B15: K5.1 | C15: =VLOOKUP(B15,'Soru Listesi'!A:C,3,0) | D15: =VLOOKUP(B15,Veriler!A:B,2,0)
B16: K6.1 | C16: =VLOOKUP(B16,'Soru Listesi'!A:C,3,0) | D16: =VLOOKUP(B16,Veriler!A:B,2,0)
B17: K7.1 | C17: =VLOOKUP(B17,'Soru Listesi'!A:C,3,0) | D17: =VLOOKUP(B17,Veriler!A:B,2,0)
B18: K8.1 | C18: =VLOOKUP(B18,'Soru Listesi'!A:C,3,0) | D18: =VLOOKUP(B18,Veriler!A:B,2,0)
B19: K8.2 | C19: =VLOOKUP(B19,'Soru Listesi'!A:C,3,0) | D19: =VLOOKUP(B19,Veriler!A:B,2,0)

Sheet K-2
B1: # | C1: =VLOOKUP(A3,'Soru Listesi'!A:F,6,0)
A2: SORU ID | C2: TESPİT | D2: İDEAL DURUM | E2: PUAN DAĞILIMI
A3: K6.1 | B3: =VLOOKUP(A3,'Soru Listesi'!A:G,3,0) | C3: =VLOOKUP(A3,Veriler!A:D,4,0) | D3: =VLOOKUP(A3,'Soru Listesi'!A:G,5,0)
A4: K7.1 | B4: =VLOOKUP(A4,'Soru Listesi'!A:G,3,0) | C4: =VLOOKUP(A4,Veriler!A:D,4,0) | D4: =VLOOKUP(A4,'Soru Listesi'!A:G,5,0)
A5: K8.1 | B5: =VLOOKUP(A5,'Soru Listesi'!A:G,3,0) | C5: =VLOOKUP(A5,Veriler!A:D,4,0) | D5: =VLOOKUP(A5,'Soru Listesi'!A:G,5,0)
A6: K8.2 | B6: =VLOOKUP(A6,'Soru Listesi'!A:G,3,0) | C6: =VLOOKUP(A6,Veriler!A:D,4,0) | D6: =VLOOKUP(A6,'Soru Listesi'!A:G,5,0)
B10: ID | C10: KONU | D10: PUAN
B11: K1.1 | C11: =VLOOKUP(B11,'Soru Listesi'!A:C,3,0) | D11: =VLOOKUP(B11,Veriler!A:B,2,0)
B12: K2.1 | C12: =VLOOKUP(B12,'Soru Listesi'!A:C,3,0) | D12: =VLOOKUP(B12,Veriler!A:B,2,0)
B13: K3.1 | C13: =VLOOKUP(B13,'Soru Listesi'!A:C,3,0) | D13: =VLOOKUP(B13,Veriler!A:B,2,0)
B14: K4.1 | C14: =VLOOKUP(B14,'Soru Listesi'!A:C,3,0) | D14: =VLOOKUP(B14,Veriler!A:B,2,0)
B15: K5.1 | C15: =VLOOKUP(B15,'Soru Listesi'!A:C,3,0) | D15: =VLOOKUP(B15,Veriler!A:B,2,0)
B16: K6.1 | C16: =VLOOKUP(B16,'Soru Listesi'!A:C,3,0) | D16: =VLOOKUP(B16,Veriler!A:B,2,0)
B17: K7.1 | C17: =VLOOKUP(B17,'Soru Listesi'!A:C,3,0) | D17: =VLOOKUP(B17,Veriler!A:B,2,0)
B18: K8.1 | C18: =VLOOKUP(B18,'Soru Listesi'!A:C,3,0) | D18: =VLOOKUP(B18,Veriler!A:B,2,0)
B19: K8.2 | C19: =VLOOKUP(B19,'Soru Listesi'!A:C,3,0) | D19: =VLOOKUP(B19,Veriler!A:B,2,0)

Sheet L-0
C2: =(CODE(UPPER(MID(CELL("dosyaadı",A1),FIND("]",CELL("dosyaadı",A1),1)+1,1)))-CODE("A")+1) & " - " &VLOOKUP(MID(CELL("dosyaadı",A1),FIND("]",CELL("dosyaadı",A1),1)+1,1),'Soru Listesi'!B:F,5,0)

Sheet L-1
B1: # | C1: =VLOOKUP(A3,'Soru Listesi'!A:F,6,0)
A2: SORU ID | C2: TESPİT | D2: İDEAL DURUM | E2: PUAN DAĞILIMI
A3: L1.1 | B3: =VLOOKUP(A3,'Soru Listesi'!A:G,3,0) | C3: =VLOOKUP(A3,Veriler!A:D,4,0) | D3: =VLOOKUP(A3,'Soru Listesi'!A:G,5,0)
A4: L2.1 | B4: =VLOOKUP(A4,'Soru Listesi'!A:G,3,0) | C4: =VLOOKUP(A4,Veriler!A:D,4,0) | D4: =VLOOKUP(A4,'Soru Listesi'!A:G,5,0)
A5: L3.1 | B5: =VLOOKUP(A5,'Soru Listesi'!A:G,3,0) | C5: =VLOOKUP(A5,Veriler!A:D,4,0) | D5: =VLOOKUP(A5,'Soru Listesi'!A:G,5,0)
A6: L4.1 | B6: =VLOOKUP(A6,'Soru Listesi'!A:G,3,0) | C6: =VLOOKUP(A6,Veriler!A:D,4,0) | D6: =VLOOKUP(A6,'Soru Listesi'!A:G,5,0)
A7: L5.1 | B7: =VLOOKUP(A7,'Soru Listesi'!A:G,3,0) | C7: =VLOOKUP(A7,Veriler!A:D,4,0) | D7: =VLOOKUP(A7,'Soru Listesi'!A:G,5,0)
B10: ID | C10: KONU | D10: PUAN
B11: L1.1 | C11: =VLOOKUP(B11,'Soru Listesi'!A:C,3,0) | D11: =VLOOKUP(B11,Veriler!A:B,2,0)
B12: L2.1 | C12: =VLOOKUP(B12,'Soru Listesi'!A:C,3,0) | D12: =VLOOKUP(B12,Veriler!A:B,2,0)
B13: L3.1 | C13: =VLOOKUP(B13,'Soru Listesi'!A:C,3,0) | D13: =VLOOKUP(B13,Veriler!A:B,2,0)
B14: L4.1 | C14: =VLOOKUP(B14,'Soru Listesi'!A:C,3,0) | D14: =VLOOKUP(B14,Veriler!A:B,2,0)
B15: L5.1 | C15: =VLOOKUP(B15,'Soru Listesi'!A:C,3,0) | D15: =VLOOKUP(B15,Veriler!A:B,2,0)
B16: L6.1 | C16: =VLOOKUP(B16,'Soru Listesi'!A:C,3,0) | D16: =VLOOKUP(B16,Veriler!A:B,2,0)
B17: L7.1 | C17: =VLOOKUP(B17,'Soru Listesi'!A:C,3,0) | D17: =VLOOKUP(B17,Veriler!A:B,2,0)
B18: L8.1 | C18: =VLOOKUP(B18,'Soru Listesi'!A:C,3,0) | D18: =VLOOKUP(B18,Veriler!A:B,2,0)
B19: L9.1 | C19: =VLOOKUP(B19,'Soru Listesi'!A:C,3,0) | D19: =VLOOKUP(B19,Veriler!A:B,2,0)

Sheet L-2
B1: # | C1: =VLOOKUP(A3,'Soru Listesi'!A:F,6,0)
A2: SORU ID | C2: TESPİT | D2: İDEAL DURUM | E2: PUAN DAĞILIMI
A3: L6.1 | B3: =VLOOKUP(A3,'Soru Listesi'!A:G,3,0) | C3: =VLOOKUP(A3,Veriler!A:D,4,0) | D3: =VLOOKUP(A3,'Soru Listesi'!A:G,5,0)
A4: L7.1 | B4: =VLOOKUP(A4,'Soru Listesi'!A:G,3,0) | C4: =VLOOKUP(A4,Veriler!A:D,4,0) | D4: =VLOOKUP(A4,'Soru Listesi'!A:G,5,0)
A5: L8.1 | B5: =VLOOKUP(A5,'Soru Listesi'!A:G,3,0) | C5: =VLOOKUP(A5,Veriler!A:D,4,0) | D5: =VLOOKUP(A5,'Soru Listesi'!A:G,5,0)
A6: L9.1 | B6: =VLOOKUP(A6,'Soru Listesi'!A:G,3,0) | C6: =VLOOKUP(A6,Veriler!A:D,4,0) | D6: =VLOOKUP(A6,'Soru Listesi'!A:G,5,0)
B10: ID | C10: KONU | D10: PUAN
B11: L1.1 | C11: =VLOOKUP(B11,'Soru Listesi'!A:C,3,0) | D11: =VLOOKUP(B11,Veriler!A:B,2,0)
B12: L2.1 | C12: =VLOOKUP(B12,'Soru Listesi'!A:C,3,0) | D12: =VLOOKUP(B12,Veriler!A:B,2,0)
B13: L3.1 | C13: =VLOOKUP(B13,'Soru Listesi'!A:C,3,0) | D13: =VLOOKUP(B13,Veriler!A:B,2,0)
B14: L4.1 | C14: =VLOOKUP(B14,'Soru Listesi'!A:C,3,0) | D14: =VLOOKUP(B14,Veriler!A:B,2,0)
B15: L5.1 | C15: =VLOOKUP(B15,'Soru Listesi'!A:C,3,0) | D15: =VLOOKUP(B15,Veriler!A:B,2,0)
B16: L6.1 | C16: =VLOOKUP(B16,'Soru Listesi'!A:C,3,0) | D16: =VLOOKUP(B16,Veriler!A:B,2,0)
B17: L7.1 | C17: =VLOOKUP(B17,'Soru Listesi'!A:C,3,0) | D17: =VLOOKUP(B17,Veriler!A:B,2,0)
B18: L8.1 | C18: =VLOOKUP(B18,'Soru Listesi'!A:C,3,0) | D18: =VLOOKUP(B18,Veriler!A:B,2,0)
B19: L9.1 | C19: =VLOOKUP(B19,'Soru Listesi'!A:C,3,0) | D19: =VLOOKUP(B19,Veriler!A:B,2,0)

Sheet M-0
C2: =(CODE(UPPER(MID(CELL("dosyaadı",A1),FIND("]",CELL("dosyaadı",A1),1)+1,1)))-CODE("A")+1) & " - " &VLOOKUP(MID(CELL("dosyaadı",A1),FIND("]",CELL("dosyaadı",A1),1)+1,1),'Soru Listesi'!B:F,5,0)

Sheet M-1
B1: # | C1: =VLOOKUP(A3,'Soru Listesi'!A:F,6,0)
A2: SORU ID | C2: TESPİT | D2: İDEAL DURUM | E2: PUAN DAĞILIMI
A3: M1.1 | B3: =VLOOKUP(A3,'Soru Listesi'!A:G,3,0) | C3: =VLOOKUP(A3,Veriler!A:D,4,0) | D3: =VLOOKUP(A3,'Soru Listesi'!A:G,5,0)
A4: M2.1 | B4: =VLOOKUP(A4,'Soru Listesi'!A:G,3,0) | C4: =VLOOKUP(A4,Veriler!A:D,4,0) | D4: =VLOOKUP(A4,'Soru Listesi'!A:G,5,0)
A5: M3.1 | B5: =VLOOKUP(A5,'Soru Listesi'!A:G,3,0) | C5: =VLOOKUP(A5,Veriler!A:D,4,0) | D5: =VLOOKUP(A5,'Soru Listesi'!A:G,5,0)
A6: M4.1 | B6: =VLOOKUP(A6,'Soru Listesi'!A:G,3,0) | C6: =VLOOKUP(A6,Veriler!A:D,4,0) | D6: =VLOOKUP(A6,'Soru Listesi'!A:G,5,0)
A7: M5.1 | B7: =VLOOKUP(A7,'Soru Listesi'!A:G,3,0) | C7: =VLOOKUP(A7,Veriler!A:D,4,0) | D7: =VLOOKUP(A7,'Soru Listesi'!A:G,5,0)
B10: ID | C10: KONU | D10: PUAN
B11: M1.1 | C11: =VLOOKUP(B11,'Soru Listesi'!A:C,3,0) | D11: =VLOOKUP(B11,Veriler!A:B,2,0)
B12: M2.1 | C12: =VLOOKUP(B12,'Soru Listesi'!A:C,3,0) | D12: =VLOOKUP(B12,Veriler!A:B,2,0)
B13: M3.1 | C13: =VLOOKUP(B13,'Soru Listesi'!A:C,3,0) | D13: =VLOOKUP(B13,Veriler!A:B,2,0)
B14: M4.1 | C14: =VLOOKUP(B14,'Soru Listesi'!A:C,3,0) | D14: =VLOOKUP(B14,Veriler!A:B,2,0)
B15: M5.1 | C15: =VLOOKUP(B15,'Soru Listesi'!A:C,3,0) | D15: =VLOOKUP(B15,Veriler!A:B,2,0)
B16: M6.1 | C16: =VLOOKUP(B16,'Soru Listesi'!A:C,3,0) | D16: =VLOOKUP(B16,Veriler!A:B,2,0)
B17: M7.1 | C17: =VLOOKUP(B17,'Soru Listesi'!A:C,3,0) | D17: =VLOOKUP(B17,Veriler!A:B,2,0)
B18: M8.1 | C18: =VLOOKUP(B18,'Soru Listesi'!A:C,3,0) | D18: =VLOOKUP(B18,Veriler!A:B,2,0)
B19: M9.1 | C19: =VLOOKUP(B19,'Soru Listesi'!A:C,3,0) | D19: =VLOOKUP(B19,Veriler!A:B,2,0)
B20: M10.1 | C20: =VLOOKUP(B20,'Soru Listesi'!A:C,3,0) | D20: =VLOOKUP(B20,Veriler!A:B,2,0)
B21: M11.1 | C21: =VLOOKUP(B21,'Soru Listesi'!A:C,3,0) | D21: =VLOOKUP(B21,Veriler!A:B,2,0)

Sheet M-2
B1: # | C1: =VLOOKUP(A3,'Soru Listesi'!A:F,6,0)
A2: SORU ID | C2: TESPİT | D2: İDEAL DURUM | E2: PUAN DAĞILIMI
A3: M6.1 | B3: =VLOOKUP(A3,'Soru Listesi'!A:G,3,0) | C3: =VLOOKUP(A3,Veriler!A:D,4,0) | D3: =VLOOKUP(A3,'Soru Listesi'!A:G,5,0)
A4: M7.1 | B4: =VLOOKUP(A4,'Soru Listesi'!A:G,3,0) | C4: =VLOOKUP(A4,Veriler!A:D,4,0) | D4: =VLOOKUP(A4,'Soru Listesi'!A:G,5,0)
A5: M8.1 | B5: =VLOOKUP(A5,'Soru Listesi'!A:G,3,0) | C5: =VLOOKUP(A5,Veriler!A:D,4,0) | D5: =VLOOKUP(A5,'Soru Listesi'!A:G,5,0)
A6: M9.1 | B6: =VLOOKUP(A6,'Soru Listesi'!A:G,3,0) | C6: =VLOOKUP(A6,Veriler!A:D,4,0) | D6: =VLOOKUP(A6,'Soru Listesi'!A:G,5,0)
A7: M10.1 | B7: =VLOOKUP(A7,'Soru Listesi'!A:G,3,0) | C7: =VLOOKUP(A7,Veriler!A:D,4,0) | D7: =VLOOKUP(A7,'Soru Listesi'!A:G,5,0)
B10: ID | C10: KONU | D10: PUAN
B11: M1.1 | C11: =VLOOKUP(B11,'Soru Listesi'!A:C,3,0) | D11: =VLOOKUP(B11,Veriler!A:B,2,0)
B12: M2.1 | C12: =VLOOKUP(B12,'Soru Listesi'!A:C,3,0) | D12: =VLOOKUP(B12,Veriler!A:B,2,0)
B13: M3.1 | C13: =VLOOKUP(B13,'Soru Listesi'!A:C,3,0) | D13: =VLOOKUP(B13,Veriler!A:B,2,0)
B14: M4.1 | C14: =VLOOKUP(B14,'Soru Listesi'!A:C,3,0) | D14: =VLOOKUP(B14,Veriler!A:B,2,0)
B15: M5.1 | C15: =VLOOKUP(B15,'Soru Listesi'!A:C,3,0) | D15: =VLOOKUP(B15,Veriler!A:B,2,0)
B16: M6.1 | C16: =VLOOKUP(B16,'Soru Listesi'!A:C,3,0) | D16: =VLOOKUP(B16,Veriler!A:B,2,0)
B17: M7.1 | C17: =VLOOKUP(B17,'Soru Listesi'!A:C,3,0) | D17: =VLOOKUP(B17,Veriler!A:B,2,0)
B18: M8.1 | C18: =VLOOKUP(B18,'Soru Listesi'!A:C,3,0) | D18: =VLOOKUP(B18,Veriler!A:B,2,0)
B19: M9.1 | C19: =VLOOKUP(B19,'Soru Listesi'!A:C,3,0) | D19: =VLOOKUP(B19,Veriler!A:B,2,0)
B20: M10.1 | C20: =VLOOKUP(B20,'Soru Listesi'!A:C,3,0) | D20: =VLOOKUP(B20,Veriler!A:B,2,0)
B21: M11.1 | C21: =VLOOKUP(B21,'Soru Listesi'!A:C,3,0) | D21: =VLOOKUP(B21,Veriler!A:B,2,0)

Sheet M-3
B1: # | C1: =VLOOKUP(A3,'Soru Listesi'!A:F,6,0)
A2: SORU ID | C2: TESPİT | D2: İDEAL DURUM | E2: PUAN DAĞILIMI
A3: M11.1 | B3: =VLOOKUP(A3,'Soru Listesi'!A:G,3,0) | C3: =VLOOKUP(A3,Veriler!A:D,4,0) | D3: =VLOOKUP(A3,'Soru Listesi'!A:G,5,0)
B10: ID | C10: KONU | D10: PUAN
B11: M1.1 | C11: =VLOOKUP(B11,'Soru Listesi'!A:C,3,0) | D11: =VLOOKUP(B11,Veriler!A:B,2,0)
B12: M2.1 | C12: =VLOOKUP(B12,'Soru Listesi'!A:C,3,0) | D12: =VLOOKUP(B12,Veriler!A:B,2,0)
B13: M3.1 | C13: =VLOOKUP(B13,'Soru Listesi'!A:C,3,0) | D13: =VLOOKUP(B13,Veriler!A:B,2,0)
B14: M4.1 | C14: =VLOOKUP(B14,'Soru Listesi'!A:C,3,0) | D14: =VLOOKUP(B14,Veriler!A:B,2,0)
