Workbook

Sheet Proje Raporu
A1: =INDEX(Bilgiler!A:A,2) -> Müşteri İsmi | H1: YIL | I1: DEVAM EDİYOR | J1: AÇIK | K1: KAPALI | L1: PERFORMANS | M1: TERMİN UYUM | N1: KAİZEN KAZANCI
N2: TL | O2: $ | P2: € | Q2: Eş Değer Ürün
H3: =YEAR(MAX(RaporTablo[[#All],[Çalışma Tarihi]])) -> 2026 | I3: =IFERROR(VLOOKUP(H3,Pivot!$A$2:$E$16,MATCH("Devam Ediyor",Pivot!$A$2:$E$2,0),0),"0") -> 11 | J3: =IFERROR(VLOOKUP(H3,Pivot!$A$2:$E$16,MATCH("Açık",Pivot!$A$2:$E$2,0),0),"0") -> 53 | K3: =IFERROR(VLOOKUP(H3,Pivot!$A$2:$E$16,MATCH("Kapalı",Pivot!$A$2:$E$2,0),0),"0") -> 43 | L3: =IFERROR(VLOOKUP(H3,Pivot!$A$2:$F$16,6,0),"0") -> 0.40186916 | M3: =IFERROR(VLOOKUP(H3,Pivot!$H$2:$K$16,4,0),0) -> 0.35514019 | N3: =IFERROR(VLOOKUP(H3,Pivot!$M$2:$P$16,MATCH("TL",Pivot!$M$2:$P$2,0),0),0) -> 0 | O3: =IFERROR(VLOOKUP(H3,Pivot!$M$2:$P$16,MATCH("$",Pivot!$M$2:$P$2,0),0),0) -> 0 | P3: =IFERROR(VLOOKUP(H3,Pivot!$M$2:$P$16,MATCH("€",Pivot!$M$2:$P$2,0),0),0) -> 0 | Q3: =IFERROR(VLOOKUP(H3,Pivot!R2:S16,2,0),0) -> 0
H4: =YEAR(MAX(RaporTablo[[#All],[Çalışma Tarihi]]))-1 -> 2025 | I4: =IFERROR(VLOOKUP(H4,Pivot!$A$2:$E$16,MATCH("Devam Ediyor",Pivot!$A$2:$E$2,0),0),"0") -> 0 | J4: =IFERROR(VLOOKUP(H4,Pivot!$A$2:$E$16,MATCH("Açık",Pivot!$A$2:$E$2,0),0),"0") -> 0 | K4: =IFERROR(VLOOKUP(H4,Pivot!$A$2:$E$16,MATCH("Kapalı",Pivot!$A$2:$E$2,0),0),"0") -> 0 | L4: =IFERROR(VLOOKUP(H4,Pivot!$A$2:$F$16,6,0),"0") -> 0 | M4: =IFERROR(VLOOKUP(H4,Pivot!$H$2:$K$16,4,0),0) -> 0 | N4: =IFERROR(VLOOKUP(H4,Pivot!$M$2:$P$16,MATCH("TL",Pivot!$M$2:$P$2,0),0),0) -> 0 | O4: =IFERROR(VLOOKUP(H4,Pivot!$M$2:$P$16,MATCH("$",Pivot!$M$2:$P$2,0),0),0) -> 0 | P4: =IFERROR(VLOOKUP(H4,Pivot!$M$2:$P$16,MATCH("€",Pivot!$M$2:$P$2,0),0),0) -> 0 | Q4: =IFERROR(VLOOKUP(H4,Pivot!R3:S17,2,0),0) -> 0
H5: =YEAR(MAX(RaporTablo[[#All],[Çalışma Tarihi]]))-2 -> 2024 | I5: =IFERROR(VLOOKUP(H5,Pivot!$A$2:$E$16,MATCH("Devam Ediyor",Pivot!$A$2:$E$2,0),0),"0") -> 0 | J5: =IFERROR(VLOOKUP(H5,Pivot!$A$2:$E$16,MATCH("Açık",Pivot!$A$2:$E$2,0),0),"0") -> 0 | K5: =IFERROR(VLOOKUP(H5,Pivot!$A$2:$E$16,MATCH("Kapalı",Pivot!$A$2:$E$2,0),0),"0") -> 0 | L5: =IFERROR(VLOOKUP(H5,Pivot!$A$2:$F$16,6,0),"0") -> 0 | M5: =IFERROR(VLOOKUP(H5,Pivot!$H$2:$K$16,4,0),0) -> 0 | N5: =IFERROR(VLOOKUP(H5,Pivot!$M$2:$P$16,MATCH("TL",Pivot!$M$2:$P$2,0),0),0) -> 0 | O5: =IFERROR(VLOOKUP(H5,Pivot!$M$2:$P$16,MATCH("$",Pivot!$M$2:$P$2,0),0),0) -> 0 | P5: =IFERROR(VLOOKUP(H5,Pivot!$M$2:$P$16,MATCH("€",Pivot!$M$2:$P$2,0),0),0) -> 0 | Q5: =IFERROR(VLOOKUP(H5,Pivot!R4:S18,2,0),0) -> 0
H6: =YEAR(MAX(RaporTablo[[#All],[Çalışma Tarihi]]))-3 -> 2023 | I6: =IFERROR(VLOOKUP(H6,Pivot!$A$2:$E$16,MATCH("Devam Ediyor",Pivot!$A$2:$E$2,0),0),"0") -> 0 | J6: =IFERROR(VLOOKUP(H6,Pivot!$A$2:$E$16,MATCH("Açık",Pivot!$A$2:$E$2,0),0),"0") -> 0 | K6: =IFERROR(VLOOKUP(H6,Pivot!$A$2:$E$16,MATCH("Kapalı",Pivot!$A$2:$E$2,0),0),"0") -> 0 | L6: =IFERROR(VLOOKUP(H6,Pivot!$A$2:$F$16,6,0),"0") -> 0 | M6: =IFERROR(VLOOKUP(H6,Pivot!$H$2:$K$16,4,0),0) -> 0 | N6: =IFERROR(VLOOKUP(H6,Pivot!$M$2:$P$16,MATCH("TL",Pivot!$M$2:$P$2,0),0),0) -> 0 | O6: =IFERROR(VLOOKUP(H6,Pivot!$M$2:$P$16,MATCH("$",Pivot!$M$2:$P$2,0),0),0) -> 0 | P6: =IFERROR(VLOOKUP(H6,Pivot!$M$2:$P$16,MATCH("€",Pivot!$M$2:$P$2,0),0),0) -> 0 | Q6: =IFERROR(VLOOKUP(H6,Pivot!R5:S19,2,0),0) -> 0
H7: TOPLAM | I7: =IFERROR(VLOOKUP(H7,Pivot!$A$2:$E$16,MATCH("Devam Ediyor",Pivot!$A$2:$E$2,0),0),"0") -> 11 | J7: =IFERROR(VLOOKUP(H7,Pivot!$A$2:$E$16,MATCH("Açık",Pivot!$A$2:$E$2,0),0),"0") -> 53 | K7: =IFERROR(VLOOKUP(H7,Pivot!$A$2:$E$16,MATCH("Kapalı",Pivot!$A$2:$E$2,0),0),"0") -> 43 | L7: =IFERROR(VLOOKUP(H7,Pivot!$A$2:$F$16,6,0),"0") -> 0.40186916 | M7: =IFERROR(VLOOKUP(H7,Pivot!$H$2:$K$16,4,0),0) -> 0.35514019 | N7: =IFERROR(VLOOKUP(H7,Pivot!$M$2:$P$16,MATCH("TL",Pivot!$M$2:$P$2,0),0),0) -> 0 | O7: =IFERROR(VLOOKUP(H7,Pivot!$M$2:$P$16,MATCH("$",Pivot!$M$2:$P$2,0),0),0) -> 0 | P7: =IFERROR(VLOOKUP(H7,Pivot!$M$2:$P$16,MATCH("€",Pivot!$M$2:$P$2,0),0),0) -> 0 | Q7: =IFERROR(VLOOKUP(H7,Pivot!R6:S20,2,0),0) -> 0
A8: Sıra No | B8: Ziyaret Haftası | C8: Çalışma Tarihi | D8: Faaliyet Konusu | E8: İyileştirme Konusu | F8: Yapılan Çalışmalar / Alınan Kararlar | G8: Çıktı | H8: Sorumlu | I8: Takip | J8: Termin | K8: Gerçekleşme Tarihi | L8: Termine Uyum | M8: Notlar | N8: Kazanç Miktarı | O8: Kazanç Birimi | P8: Kaizen Kazancı | Q8: Eş Değer Ürün | R8: Sene | S8: Sıra No | T8: Eslestirme
A9: 1 | B9: 25 | C9: 46189 | D9: A3 | E9: VERİMLİLİK | F9: A3 EĞİTİMİNE KATILAN ARKADAŞLAR KENDİ ALANLARINDAN KİŞİ BAŞI EN AZ BİR ADET PROJE KONUSU BELİRLEYECEK | G9: VERİMLİLİK | H9: Gözde Tohumci | I9: Açık | J9: 46195 | K9: 46189 | L9: ZAMANINDA | M9: A3 | O9: ₺ | R9: 2026 | S9: 1 | T9: 202625A3
A10: 2 | B10: 25 | C10: 46189 | D10: TPM | E10: VERİMLİLİK | F10: OPERATÖR MÜDAHALESİNE UYGUN DURUŞLAR İÇİN ARIZA AKIŞ DİAGAMI HAZIRLANACAK | G10: VERİMLİLİK | H10: Barış Avcı | I10: Açık | J10: 46195 | K10: 46189 | L10: ZAMANINDA | M10: AKIŞ DİAGRAMI | O10: ₺ | R10: 2026 | S10: 2 | T10: 202625TPM
A11: 3 | B11: 25 | C11: 46189 | D11: TPM | E11: VERİMLİLİK | F11: ARIZA MÜDAHELE İÇİN TEK NOKTA DERSİ ŞEKLİNDE EĞİTİM DÖKÜMANLARI HAZIRLANACAK | G11: VERİMLİLİK | H11: Barış Avcı | I11: Açık | J11: 46195 | K11: 46189 | L11: ZAMANINDA | M11: AKIŞ DİAGRAMI | O11: ₺ | R11: 2026 | S11: 3 | T11: 202625TPM
A12: 4 | B12: 25 | C12: 46189 | D12: 5S | E12: 5S | F12: 26. HAFTAYA KAYAR HATTINDA 5s FAALİYETİ PLANLANACAK | G12: ÜRETKENLİK | H12: Gözde Tohumci | I12: Açık | J12: 46196 | K12: 46189 | L12: ZAMANINDA | M12: 5S | O12: ₺ | R12: 2026 | S12: 4 | T12: 2026255S
A13: 5 | B13: 25 | C13: 46189 | D13: SAHA YÖNETİMİ | E13: GÜVENLİK | F13: SAFETY PATROL DEVRİYESİ YAPILDI | G13: ÜRETKENLİK | H13: Gözde Tohumci | I13: Kapalı | J13: 46189 | K13: 46189 | L13: GECİKME | O13: ₺ | R13: 2026 | S13: 5 | T13: 202625SAHA YÖNETİMİ
A14: 6 | B14: 25 | C14: 46188 | D14: EĞİTİM | E14: VERİMLİLİK | F14: A3 EĞİTİMİ YAPILDI | G14: VERİMLİLİK | H14: Kemal Doğan | I14: Kapalı | J14: 46188 | K14: 46188 | L14: ZAMANINDA | M14: A3 | O14: ₺ | R14: 2026 | S14: 6 | T14: 202625EĞİTİM
A15: 7 | B15: 24 | C15: 46182 | D15: SMED | E15: VERİMLİLİK | F15: 2. İŞ ADIMI İşlem sırasında takım çantası yanında taşınacak | G15: ZAMAN | H15: Ersan Sezgin | I15: Açık | J15: 46192 | K15: 46182 | L15: ZAMANINDA | M15: PNSZ 07 SMED | O15: ₺ | R15: 2026 | S15: 7 | T15: 202624SMED
A16: 8 | B16: 24 | C16: 46182 | D16: SMED | E16: VERİMLİLİK | F16: 6. İŞ ADIMI Tekrar kullanılmayacak takım vb ürünlerin temizliği setup bittikten sonra yapılacak | G16: ZAMAN | H16: Ersan Sezgin | I16: Açık | J16: 46192 | K16: 46182 | L16: ZAMANINDA | M16: PNSZ 07 SMED | O16: ₺ | R16: 2026 | S16: 8 | T16: 202624SMED
A17: 9 | B17: 24 | C17: 46182 | D17: SMED | E17: VERİMLİLİK | F17: 7. İŞ ADIMI Kirlilik sebebi basınçlı hava temizlenecek. | G17: ZAMAN | H17: Ersan Sezgin | I17: Açık | J17: 46197 | K17: 46182 | L17: ZAMANINDA | M17: PNSZ 07 SMED | O17: ₺ | R17: 2026 | S17: 9 | T17: 202624SMED
A18: 10 | B18: 24 | C18: 46182 | D18: SMED | E18: VERİMLİLİK | F18: 12. İŞ ADIMI İş standartı oluşturulurken bu işlem eklenmeyecek. | G18: ZAMAN | H18: Ersan Sezgin | I18: Açık | J18: 46198 | K18: 46182 | L18: ZAMANINDA | M18: PNSZ 07 SMED | O18: ₺ | R18: 2026 | S18: 10 | T18: 202624SMED
A19: 11 | B19: 24 | C19: 46182 | D19: SMED | E19: VERİMLİLİK | F19: 13. İŞ ADIMI İş standartı oluşturulurken bu işlem eklenmeyecek. | G19: ZAMAN | H19: Emre Soylu | I19: Açık | J19: 46199 | K19: 46182 | L19: ZAMANINDA | M19: PNSZ 07 SMED | O19: ₺ | R19: 2026 | S19: 11 | T19: 202624SMED
A20: 12 | B20: 24 | C20: 46182 | D20: SMED | E20: VERİMLİLİK | F20: 14. İŞ ADIMI Arkadan yükleme yapılan tezgahlarda hava kanalı T ile ikiye ayrılacak ve tezgahın ön ve arka kısmına hava tabancası eklenecek. | G20: ZAMAN | H20: Emre Soylu | I20: Açık | J20: 46223 | K20: 46182 | L20: ZAMANINDA | M20: PNSZ 07 SMED | O20: ₺ | R20: 2026 | S20: 12 | T20: 202624SMED
A21: 13 | B21: 24 | C21: 46182 | D21: SMED | E21: VERİMLİLİK | F21: 16. İŞ ADIMI Dayama civataları sökülüp dayama yatakdan çıkartıldıktan sonra hemen yeni dayama takılması için yatak temizligi yapılacak. | G21: ZAMAN | H21: Emre Soylu | I21: Açık | J21: 46192 | K21: 46182 | L21: ZAMANINDA | M21: PNSZ 07 SMED | O21: ₺ | R21: 2026 | S21: 13 | T21: 202624SMED
A22: 14 | B22: 24 | C22: 46182 | D22: SMED | E22: VERİMLİLİK | F22: 18. İŞ ADIMI 16. Adımdaki işlem yapılacak. | G22: ZAMAN | H22: Emre Soylu | I22: Açık | J22: 46197 | K22: 46182 | L22: ZAMANINDA | M22: PNSZ 07 SMED | O22: ₺ | R22: 2026 | S22: 14 | T22: 202624SMED
A23: 15 | B23: 24 | C23: 46182 | D23: SMED | E23: VERİMLİLİK | F23: 27. İŞ ADIMI Setup başlamadan önce kullanılacak ara kagıtlar tezgahın yanına getirilecek. | G23: ZAMAN | H23: Emre Soylu | I23: Açık | J23: 46198 | K23: 46182 | L23: ZAMANINDA | M23: PNSZ 07 SMED | O23: ₺ | R23: 2026 | S23: 15 | T23: 202624SMED
A24: 16 | B24: 24 | C24: 46182 | D24: SMED | E24: VERİMLİLİK | F24: 34, 35, 36, 37. İŞ ADIMI Referans bazlı ara flans tasarımı ve üretimi yapılacak yapılan üretimden sonra ürünlerin temas yüzeyi olmayan kısımlarına referans numarası delık çapı ve boy bilgileri lazer ile işlenecek. | G24: ZAMAN | H24: Emre Soylu | I24: Açık | J24: 46190 | K24: 46182 | L24: GECİKME | M24: PNSZ 07 SMED | O24: ₺ | R24: 2026 | S24: 16 | T24: 202624SMED
A25: 17 | B25: 24 | C25: 46182 | D25: SMED | E25: VERİMLİLİK | F25: 39, 40. İŞ ADIMI Taş sökme ve takma eğitimi verilecek. | G25: ZAMAN | H25: Ersan Sezgin | I25: Açık | J25: 46191 | K25: 46182 | L25: ZAMANINDA | M25: PNSZ 07 SMED | O25: ₺ | R25: 2026 | S25: 17 | T25: 202624SMED
... A48: 40 | B48: 18 | C48: 46140 | D48: OEE | E48: VERİMLİLİK | F48: ÖNCE ÇOK KOŞAN ÜRÜNLERDEN BAŞLAYARAK CT SÜRELERİ PLANLAMAYLA PAYLAŞILACAK | G48: VERİMLİLİK | H48: Emre Soylu | I48: Devam Ediyor | J48: 46154 | K48: 46140 | L48: GECİKME | M48: PLANLAMA ÜRETİM VERİ FARKI | O48: ₺ | R48: 2026 | S48: 40 | T48: 202618OEE
A49: 41 | B49: 18 | C49: 46140 | D49: GÖRSEL YÖNETİM | E49: VERİMLİLİK | F49: PFUS PERFORMANS TAKİBİ BAŞLATILACAK (ASAKAİ) | G49: VERİMLİLİK | H49: Gözde Tohumci | I49: Kapalı | J49: 46147 | K49: 46140 | L49: GECİKME | O49: ₺ | R49: 2026 | S49: 41 | T49: 202618GÖRSEL YÖNETİM
A50: 42 | B50: 18 | C50: 46139 | D50: KALİTE | E50: KALİTE | F50: TCNC DURUŞ SONRASI ISITMA PROGRAMI TASARIMI | G50: KALİTE | H50: Emre Soylu | I50: Açık | J50: 46154 | K50: 46139 | L50: GECİKME | M50: ÇAP BÜYÜK HATASI | O50: ₺ | R50: 2026 | S50: 42 | T50: 202618KALİTE
A51: 43 | B51: 18 | C51: 46139 | D51: KALİTE | E51: KALİTE | F51: OTOMATİK OFSET TCNC | G51: KALİTE | H51: Emre Soylu | I51: Açık | J51: 46154 | K51: 46139 | L51: GECİKME | M51: ÇAP BÜYÜK HATASI | O51: ₺ | R51: 2026 | S51: 43 | T51: 202618KALİTE
A52: 44 | B52: 18 | C52: 46139 | D52: KALİTE | E52: KALİTE | F52: TEZGAH BAŞINDAN AYRILMALARDA NOMİNALE ALINMA | G52: KALİTE | H52: Emre Soylu | I52: Açık | J52: 46154 | K52: 46139 | L52: GECİKME | M52: ÇAP BÜYÜK HATASI | O52: ₺ | R52: 2026 | S52: 44 | T52: 202618KALİTE
A53: 45 | B53: 18 | C53: 46139 | D53: STANDART İŞ | E53: KALİTE | F53: TCNC İŞ STD. OLUŞTURMA | G53: KALİTE | H53: Emre Soylu | I53: Açık | J53: 46147 | K53: 46139 | L53: GECİKME | M53: ÇAP BÜYÜK HATASI | O53: ₺ | R53: 2026 | S53: 45 | T53: 202618STANDART İŞ
A54: 46 | B54: 18 | C54: 46139 | D54: STANDART İŞ | E54: KALİTE | F54: TCNC ZAMAN ETÜDÜ | G54: KALİTE | H54: Emre Soylu | I54: Açık | J54: 46147 | K54: 46139 | L54: GECİKME | M54: ÇAP BÜYÜK HATASI | O54: ₺ | R54: 2026 | S54: 46 | T54: 202618STANDART İŞ
A55: 47 | B55: 18 | C55: 46139 | D55: KALİTE | E55: KALİTE | F55: FARKLI MODEL TCNC LERDE MİN. MAX. OVALLİK ÇALIŞMASI | G55: KALİTE | H55: Pınar Yılmaz | I55: Açık | J55: 46147 | K55: 46139 | L55: GECİKME | M55: ÇAP BÜYÜK HATASI | O55: ₺ | R55: 2026 | S55: 47 | T55: 202618KALİTE
A56: 48 | B56: 18 | C56: 46139 | D56: KALİTE | E56: KALİTE | F56: HAVALI GUAGE TASARIMI | G56: KALİTE | H56: Sezayi Parlakkılıç | I56: Açık | J56: 46147 | K56: 46139 | L56: GECİKME | M56: ÇAP BÜYÜK HATASI | O56: ₺ | R56: 2026 | S56: 48 | T56: 202618KALİTE
A57: 49 | B57: 17 | C57: 46133 | D57: KALİTE | E57: KALİTE | F57: A00154403 NUMARALI REFERANS DA PAS PROBLEMİ İÇİN KALICI KARŞI ÖNLEM ALINANA KADAR SON KONTROL GİRİŞİNDEKİ FKK ALANINDA FİFO TAKİBİ YAPILACAK. | G57: KALİTE | H57: Sanem Dokumacı | I57: Kapalı | J57: 46134 | K57: 46133 | L57: GECİKME | M57: FİFO KONTROL | O57: ₺ | R57: 2026 | S57: 49 | T57: 202617KALİTE
A58: 50 | B58: 17 | C58: 46133 | D58: KALİTE | E58: KALİTE | F58: A00154403 NUMARALI REFERANS DA PAS PROBLEMİ İÇİNOVALAMA YAGI SONRASI ÜRÜN TAKP | G58: KALİTE | H58: Doğukan Topçu | I58: Devam Ediyor | J58: 46153 | K58: 46133 | L58: GECİKME | M58: OVALAMA YAĞI | O58: ₺ | R58: 2026 | S58: 50 | T58: 202617KALİTE
A59: 51 | B59: 17 | C59: 46133 | D59: KALİTE | E59: KALİTE | F59: BLİSTER PNSZ ÜRETİM HATTI DENEMESİ | G59: KALİTE | H59: Doğukan Topçu | I59: Devam Ediyor | J59: 46139 | K59: 46133 | L59: GECİKME | M59: BLİSTER DENEME | O59: ₺ | R59: 2026 | S59: 51 | T59: 202617KALİTE
A60: 52 | B60: 17 | C60: 46133 | D60: KALİTE | E60: KALİTE | F60: FREZE BOR YAĞ STD. KONTROLÜ | G60: KALİTE | H60: Doğukan Topçu | I60: Devam Ediyor | J60: 46139 | K60: 46133 | L60: GECİKME | M60: FREZE BOR YAĞ | O60: ₺ | R60: 2026 | S60: 52 | T60: 202617KALİTE
A61: 53 | B61: 17 | C61: 46133 | D61: KALİTE | E61: KALİTE | F61: FRZ, TCNCBOR YAĞ ORANLARI KONTROLÜ | G61: KALİTE | H61: Doğukan Topçu | I61: Devam Ediyor | J61: 46139 | K61: 46133 | L61: GECİKME | M61: YAĞ ORANI KONTROL | O61: ₺ | R61: 2026 | S61: 53 | T61: 202617KALİTE
... A80: 72 | B80: 14 | C80: 46113 | D80: TPM | E80: VERİMLİLİK | F80: MTTR-MTBF TAKİP KONUSUNDA BAKIM GRUBU İLE ÖRNEK DOKÜMAN PAYLAŞILDI. ASAKAİ DE BU FORMLAR YARDIMIYLE MTTR MTBF GRAFİKLERİ HAZIRLANACAK | G80: ÜRETKENLİK | H80: Barış Avcı | I80: Kapalı | J80: 46118 | K80: 46118 | L80: ZAMANINDA | M80: ASAKAİ | O80: ₺ | R80: 2026 | S80: 72 | T80: 202614TPM
...

Sheet DashBoard
S1: EĞİTİM SAYISI | U1: =INDEX(Bilgiler!H:H,2) -> 0
S3: PERSONEL SAYISI | U3: =INDEX(Bilgiler!I:I,2) -> 0
S5: EĞİTİM SAATİ | U5: =INDEX(Bilgiler!J:J,2) -> 0
S8: TOPLAM AKSİYON SAYISI | U8: =COUNTA('Proje Raporu'!B:B)-2 -> 106
S10: TOPLAM KAİZEN SAYISI | U10: =COUNTA('Proje Raporu'!G:G)-1 -> 107

Sheet Pivot
A1: Say Ziyaret Haftası | B1: AKSİYON DURUMU | H1: Say Ziyaret Haftası | I1: AKSİYON DURUMU | M1: Toplam Kaizen Kazancı | N1: AKSİYON DURUMU | R1: YIL | S1: Toplam Eş Değer Ürün
A2: YIL | B2: Açık | C2: Devam Ediyor | D2: Kapalı | F2: Performans | H2: YIL | I2: GECİKME | J2: ZAMANINDA | K2: Termin Performans | M2: YIL | R2: 2026
A3: 2026 | B3: 53 | C3: 11 | D3: 43 | F3: {=IFERROR(INDEX($A:$Z,ROW(),MATCH("Kapalı",$2:$2,0)) / SUM( INDEX($A:$Z,ROW(),MATCH("Açık",$2:$2,0)), INDEX($A:$Z,ROW(),MATCH("Kapalı",$2:$2,0)), INDEX($A:$Z,ROW(),MATCH("Devam Ediyor",$2:$2,0)) ),"")} -> 0.40186916 | H3: 2026 | I3: 69 | J3: 38 | K3: =IFERROR(J3/(J3+I3),"") -> 0.35514019 | M3: TOPLAM | R3: TOPLAM | U3: Aksiyon Sayısı | V3: AKSİYON DURUMU | Y3: Aksiyon Sayısı | Z3: AKSİYON DURUMU | AE3: Faaliyet Konusu | AF3: Aksiyon Sayısı | AH3: İyileştirme Konusu | AI3: Aksiyon Sayısı | AK3: Çıktı | AL3: Aksiyon Sayısı | AN3: Satır Etiketleri | AO3: OPEX | AP3: OEE | AQ3: Lead Time
A4: TOPLAM | B4: 53 | C4: 11 | D4: 43 | F4: {=IFERROR(INDEX($A:$Z,ROW(),MATCH("Kapalı",$2:$2,0)) / SUM( INDEX($A:$Z,ROW(),MATCH("Açık",$2:$2,0)), INDEX($A:$Z,ROW(),MATCH("Kapalı",$2:$2,0)), INDEX($A:$Z,ROW(),MATCH("Devam Ediyor",$2:$2,0)) ),"")} -> 0.40186916 | H4: TOPLAM | I4: 69 | J4: 38 | K4: =IFERROR(J4/(J4+I4),"") -> 0.35514019 | U4: SORUMLU | V4: GECİKME | W4: ZAMANINDA | Y4: SORUMLU | Z4: Açık | AA4: Devam Ediyor | AB4: Kapalı | AE4: EĞİTİM | AF4: 9 | AH4: 5S | AI4: 2 | AK4: KAZA RİSKİ | AL4: 1 | AN4: (boş)
F5: {=IFERROR(INDEX($A:$Z,ROW(),MATCH("Kapalı",$2:$2,0)) / SUM( INDEX($A:$Z,ROW(),MATCH("Açık",$2:$2,0)), INDEX($A:$Z,ROW(),MATCH("Kapalı",$2:$2,0)), INDEX($A:$Z,ROW(),MATCH("Devam Ediyor",$2:$2,0)) ),"")} | K5: =IFERROR(J5/(J5+I5),"") | U5: Kemal Doğan | V5: 2 | W5: 11 | Y5: Kemal Doğan | AA5: 1 | AB5: 12 | AE5: GÖRSEL YÖNETİM | AF5: 12 | AH5: ÇEVRE | AI5: 2 | AK5: MOTIVASYON | AL5: 4 | AN5: Genel Toplam
F6: {=IFERROR(INDEX($A:$Z,ROW(),MATCH("Kapalı",$2:$2,0)) / SUM( INDEX($A:$Z,ROW(),MATCH("Açık",$2:$2,0)), INDEX($A:$Z,ROW(),MATCH("Kapalı",$2:$2,0)), INDEX($A:$Z,ROW(),MATCH("Devam Ediyor",$2:$2,0)) ),"")} | K6: =IFERROR(J6/(J6+I6),"") | U6: Emre Soylu | V6: 18 | W6: 6 | Y6: Emre Soylu | Z6: 18 | AA6: 4 | AB6: 2 | AE6: KAİZEN | AF6: 1 | AH6: GÜVENLİK | AI6: 3 | AK6: ÜRETKENLİK | AL6: 19
F7: {=IFERROR(INDEX($A:$Z,ROW(),MATCH("Kapalı",$2:$2,0)) / SUM( INDEX($A:$Z,ROW(),MATCH("Açık",$2:$2,0)), INDEX($A:$Z,ROW(),MATCH("Kapalı",$2:$2,0)), INDEX($A:$Z,ROW(),MATCH("Devam Ediyor",$2:$2,0)) ),"")} | K7: =IFERROR(J7/(J7+I7),"") | U7: Doğukan Topçu | V7: 7 | W7: 1 | Y7: Doğukan Topçu | Z7: 3 | AA7: 4 | AB7: 1 | AE7: SAHA YÖNETİMİ | AF7: 7 | AH7: KALİTE | AI7: 26 | AK7: VERİMLİLİK | AL7: 23
F8: {=IFERROR(INDEX($A:$Z,ROW(),MATCH("Kapalı",$2:$2,0)) / SUM( INDEX($A:$Z,ROW(),MATCH("Açık",$2:$2,0)), INDEX($A:$Z,ROW(),MATCH("Kapalı",$2:$2,0)), INDEX($A:$Z,ROW(),MATCH("Devam Ediyor",$2:$2,0)) ),"")} | K8: =IFERROR(J8/(J8+I8),"") | U8: Sanem Dokumacı | V8: 11 | Y8: Sanem Dokumacı | AB8: 11 | AE8: STANDART İŞ | AF8: 2 | AH8: MOTİVASYON | AI8: 6 | AK8: YETENEK | AL8: 4
F9: {=IFERROR(INDEX($A:$Z,ROW(),MATCH("Kapalı",$2:$2,0)) / SUM( INDEX($A:$Z,ROW(),MATCH("Açık",$2:$2,0)), INDEX($A:$Z,ROW(),MATCH("Kapalı",$2:$2,0)), INDEX($A:$Z,ROW(),MATCH("Devam Ediyor",$2:$2,0)) ),"")} | K9: =IFERROR(J9/(J9+I9),"") | U9: Gözde Tohumci | V9: 7 | W9: 6 | Y9: Gözde Tohumci | Z9: 2 | AB9: 11 | AE9: VSM | AF9: 11 | AH9: VERİMLİLİK | AI9: 68 | AK9: ZAMAN | AL9: 21
F10: {=IFERROR(INDEX($A:$Z,ROW(),MATCH("Kapalı",$2:$2,0)) / SUM( INDEX($A:$Z,ROW(),MATCH("Açık",$2:$2,0)), INDEX($A:$Z,ROW(),MATCH("Kapalı",$2:$2,0)), INDEX($A:$Z,ROW(),MATCH("Devam Ediyor",$2:$2,0)) ),"")} | K10: =IFERROR(J10/(J10+I10),"") | U10: Uğur Yılmaz | V10: 2 | Y10: Uğur Yılmaz | Z10: 2 | AE10: AKIŞ İYİLEŞTİRME | AF10: 3 | AH10: TOPLAM | AI10: 107 | AK10: KALİTE | AL10: 27
F11: {=IFERROR(INDEX($A:$Z,ROW(),MATCH("Kapalı",$2:$2,0)) / SUM( INDEX($A:$Z,ROW(),MATCH("Açık",$2:$2,0)), INDEX($A:$Z,ROW(),MATCH("Kapalı",$2:$2,0)), INDEX($A:$Z,ROW(),MATCH("Devam Ediyor",$2:$2,0)) ),"")} | K11: =IFERROR(J11/(J11+I11),"") | U11: Emine Doğru | V11: 1 | Y11: Emine Doğru | Z11: 1 | AE11: 5S | AF11: 3 | AK11: STOK | AL11: 8
F12: {=IFERROR(INDEX($A:$Z,ROW(),MATCH("Kapalı",$2:$2,0)) / SUM( INDEX($A:$Z,ROW(),MATCH("Açık",$2:$2,0)), INDEX($A:$Z,ROW(),MATCH("Kapalı",$2:$2,0)), INDEX($A:$Z,ROW(),MATCH("Devam Ediyor",$2:$2,0)) ),"")} | K12: =IFERROR(J12/(J12+I12),"") | U12: Ersan Sezgin | V12: 3 | W12: 7 | Y12: Ersan Sezgin | Z12: 9 | AA12: 1 | AE12: KALİTE | AF12: 23 | AK12: TOPLAM | AL12: 107
F13: {=IFERROR(INDEX($A:$Z,ROW(),MATCH("Kapalı",$2:$2,0)) / SUM( INDEX($A:$Z,ROW(),MATCH("Açık",$2:$2,0)), INDEX($A:$Z,ROW(),MATCH("Kapalı",$2:$2,0)), INDEX($A:$Z,ROW(),MATCH("Devam Ediyor",$2:$2,0)) ),"")} | K13: =IFERROR(J13/(J13+I13),"") | U13: Sezayi Parlakkılıç | V13: 1 | W13: 1 | Y13: Sezayi Parlakkılıç | Z13: 1 | AB13: 1 | AE13: OEE | AF13: 4
F14: {=IFERROR(INDEX($A:$Z,ROW(),MATCH("Kapalı",$2:$2,0)) / SUM( INDEX($A:$Z,ROW(),MATCH("Açık",$2:$2,0)), INDEX($A:$Z,ROW(),MATCH("Kapalı",$2:$2,0)), INDEX($A:$Z,ROW(),MATCH("Devam Ediyor",$2:$2,0)) ),"")} | K14: =IFERROR(J14/(J14+I14),"") | U14: Pınar Yılmaz | V14: 4 | Y14: Pınar Yılmaz | Z14: 4 | AE14: SMED | AF14: 27
F15: {=IFERROR(INDEX($A:$Z,ROW(),MATCH("Kapalı",$2:$2,0)) / SUM( INDEX($A:$Z,ROW(),MATCH("Açık",$2:$2,0)), INDEX($A:$Z,ROW(),MATCH("Kapalı",$2:$2,0)), INDEX($A:$Z,ROW(),MATCH("Devam Ediyor",$2:$2,0)) ),"")} | K15: =IFERROR(J15/(J15+I15),"") | U15: Gamze Öyekcin | V15: 6 | Y15: Gamze Öyekcin | Z15: 6 | AE15: A3 | AF15: 1
F16: {=IFERROR(INDEX($A:$Z,ROW(),MATCH("Kapalı",$2:$2,0)) / SUM( INDEX($A:$Z,ROW(),MATCH("Açık",$2:$2,0)), INDEX($A:$Z,ROW(),MATCH("Kapalı",$2:$2,0)), INDEX($A:$Z,ROW(),MATCH("Devam Ediyor",$2:$2,0)) ),"")} | K16: =IFERROR(J16/(J16+I16),"") | U16: Barış Avcı | V16: 2 | W16: 6 | Y16: Barış Avcı | Z16: 6 | AB16: 2 | AE16: TPM | AF16: 4
U17: Gülçin Başçiftci | V17: 1 | Y17: Gülçin Başçiftci | Z17: 1 | AE17: TOPLAM | AF17: 107
U18: Derya Gümüşoğlu | V18: 4 | Y18: Derya Gümüşoğlu | AA18: 1 | AB18: 3
U19: TOPLAM | V19: 69 | W19: 38 | Y19: TOPLAM | Z19: 53 | AA19: 11 | AB19: 43

Sheet Bilgiler
A1: FirmaAdi | C1: DegerlendirmeNo | D1: Opex Puanı | E1: OEE | F1: Lead Time | H1: EgitimSayisi | I1: EgitimPersoneli | J1: EgitimSaati | L1: FaaliyetKonusuText | M1: FaaliyetYili | N1: FaaliyetHaftasi | O1: Eslestirme
A2: Müşteri İsmi | H2: 0
